Workbook
Name counts: shee2!$AN$10:$AN$1621
Name crack_s: shee2!$M$10:$M$1621
Name crack_s_index: shee2!$O$10:$O$1621
Name crack_t_index: shee2!$R$10:$R$1621
Name crack_ts: shee2!$P$10:$P$1621
Name d_s: shee2!$AE$10:$AE$1621
Name database1: shee2!$A$9:$AI$1621
Name database2: shee2!$AK$9:$AS$1621
Name database3: shee2!$AU$9:$AZ$1621
Name ee_s: shee2!$AB$10:$AB$1621
Name es_s: shee2!#REF!
Name n: shee2!$R$10:$R$695
Name patch_s: shee2!$V$10:$V$1621
Name pot_s: shee2!$S$10:$S$1621
Name rave_index: shee2!$AA$10:$AA$1621
Name rough_index: shee2!$AS$10:$AS$1621
Name rslpd: shee2!$AZ$10:$AZ$1621
Name rufmkm: shee2!$AQ$10:$AQ$1621
Name rufmmkm: shee2!$AR$10:$AR$1621
Name rut_index: shee2!$L$10:$L$1621
Name rut_s: shee2!$J$10:$J$1621
Name rv_s: shee2!$Y$10:$Y$1621

Sheet shee2
A1: Road Condition and Roughness Survey Data - 2026-27
A3: ="Route: "&A10&IF(B10="NB"," ( Karachi- Torkham )",IF(B10="NB"," (North Bound)","")) -> Route: N-5 ( Karachi- Torkham )
A4: =VLOOKUP(A10,'Sheet1 (2)'!A88:D118,4,FALSE) -> Karachi - Hyderabad - Multan - Lahore - Peshawar - Torkham
A6: PAVEMENT CONDITION SURVEY | AK6: ROAD ROUGHNESS SURVEY | AU6: REMAINING SERVICE LIFE
A7: Route | B7: Direction | C7: Km. | D7: Surface | E7: Road Width (m) | F7: Left Shoulder | H7: Right Shoulder | J7: Rutting | M7: Cracking (Structural) | P7: Cracking (Thermal) | S7: Potholes | V7: Patching | Y7: Ravelling | AB7: Edge Erosion | AE7: Drainage | AH7: Remarks | AI7: Date | AK7: Route | AL7: Direction | AM7: Km | AN7: Roughness Counts | AO7: Remarks | AP7: Date | AQ7: Roughness
F8: Width (m) | G8: Type | H8: Width (m) | I8: Type | J8: Severity | K8: Extent | L8: Index | M8: Severity | N8: Extent | O8: Index | P8: Severity | Q8: Extent | R8: Index | S8: Severity | T8: Extent | U8: Index | V8: Severity | W8: Extent | X8: Index | Y8: Severity | Z8: Extent | AA8: Index | AB8: Severity | AC8: Extent | AD8: Index | AE8: Severity | AF8: Extent | AG8: Index | AQ8: m/km | AR8: mm/km | AS8: Index | AU8: Rutting | AV8: Cracking (Structural) | AW8: Cracking (Thermal) | AX8: Ravelling | AY8: Roughness | AZ8: Pavement | BA8: Status
A9: route | B9: dir | C9: km | D9: stype | E9: rd-w | F9: sh-lw | G9: sh-lt | H9: sh-rw | I9: sh-rt | J9: rut-s | K9: rut-e | L9: ri | M9: crack-s | N9: crack-e | O9: ci | P9: crack-ts | Q9: crack-te | R9: ci | S9: pot-s | T9: pot-e | U9: pi | V9: Patch-s | W9: Patch-e | X9: pti | Y9: rv-s | Z9: rv-e | AA9: rvi | AB9: ee-s | AC9: ee-e | AD9: eei | AE9: d-s | AF9: d-e | AG9: di | AK9: Route | AL9: dir | AM9: km | AN9: count | AO9: rem | AP9: Date | AQ9: rufmkm | AR9: rufmmkm | AS9: gi | AU9: rslrd | AV9: rslcds | AW9: rslcdt | AX9: rslrv | AY9: rslgd | AZ9: rslpd
A10: N-5 | B10: NB | C10: 150 | D10: A | E10: 8 | F10: 1 | G10: A | H10: 0.5 | I10: A | J10: x | K10: x | L10: =VLOOKUP(CONCATENATE(J10,K10),'Sheet1 (2)'!$J$6:$K$26,2,FALSE) -> 0 | M10: x | N10: x | O10: =VLOOKUP(CONCATENATE(M10,N10),'Sheet1 (2)'!$L$6:$M$26,2,FALSE) -> 0 | P10: x | Q10: x | R10: =VLOOKUP(CONCATENATE(P10,Q10),'Sheet1 (2)'!$N$6:$O$26,2,FALSE) -> 0 | S10: x | T10: x | U10: =VLOOKUP(CONCATENATE(S10,T10),'Sheet1 (2)'!$P$6:$Q$26,2,FALSE) -> 0 | V10: x | W10: x | X10: =VLOOKUP(CONCATENATE(V10,W10),'Sheet1 (2)'!$R$6:$S$26,2,FALSE) -> 0 | Y10: c | Z10: d | AA10: =VLOOKUP(CONCATENATE(Y10,Z10),'Sheet1 (2)'!$T$6:$U$26,2,FALSE) -> 56.25 | AB10: x | AC10: x | AD10: =VLOOKUP(CONCATENATE(AB10,AC10),'Sheet1 (2)'!$X$6:$Y$26,2,FALSE) -> 0 | AE10: b | AF10: e | AG10: =VLOOKUP(CONCATENATE(AE10,AF10),'Sheet1 (2)'!$Z$6:$AA$26,2,FALSE) -> 66 | AI10: 26-12-2025 | AK10: N-5 | AL10: NB | AM10: =C10 -> 150 | AO10: 150 MP JAMSHOR TOLL PLAZA | AQ10: 3.5562237 | AS10: =LOOKUP(rufmkm,'Sheet1 (2)'!$V$62:$V$71,'Sheet1 (2)'!$W$62:$W$71) -> 40 | AU10: =IF(IF(D10='Sheet1 (2)'!$C$69,'Sheet1 (2)'!$D$69*('Sheet1 (2)'!$D$72-rut_index)/'Sheet1 (2)'!$D$72,IF(shee2!D10='Sheet1 (2)'!$C$70,'Sheet1 (2)'!$D$70*('Sheet1 (2)'!$D$72-rut_index)/'Sheet1 (2)'!$D$72,IF(shee2!D10='Sheet1 (2)'!$C$71,'Sheet1 (2)'!$D$71*('Sheet1 (2)'!$D$72-rut_index)/'Sheet1 (2)'!$D$72)))<0,0,IF(D10='Sheet1 (2)'!$C$69,'Sheet1 (2)'!$D$69*('Sheet1 (2)'!$D$72-rut_index)/'Sheet1 (2)'!$D$72,IF(shee2!D10='Sheet1 (2)'!$C$70,'Sheet1 (2)'!$D$70*('Sheet1 (2)'!$D$72-rut_index)/'Sheet1 (2)'!$D$72,IF(shee2!D10='Sheet1 (2)'!$C$71,'Sheet1 (2)'!$D$71*('Sheet1 (2)'!$D$72-rut_index)/'Sheet1 (2)'!$D$72)))) -> 5 | AV10: =IF(IF(D10='Sheet1 (2)'!$C$69,'Sheet1 (2)'!$D$69*('Sheet1 (2)'!$D$72-crack_s_index)/'Sheet1 (2)'!$D$72,IF(shee2!D10='Sheet1 (2)'!$C$70,'Sheet1 (2)'!$D$70*('Sheet1 (2)'!$D$72-crack_s_index)/'Sheet1 (2)'!$D$72,IF(shee2!D10='Sheet1 (2)'!$C$71,'Sheet1 (2)'!$D$71*('Sheet1 (2)'!$D$72-crack_s_index)/'Sheet1 (2)'!$D$72)))<0,0,IF(D10='Sheet1 (2)'!$C$69,'Sheet1 (2)'!$D$69*('Sheet1 (2)'!$D$72-crack_s_index)/'Sheet1 (2)'!$D$72,IF(shee2!D10='Sheet1 (2)'!$C$70,'Sheet1 (2)'!$D$70*('Sheet1 (2)'!$D$72-crack_s_index)/'Sheet1 (2)'!$D$72,IF(shee2!D10='Sheet1 (2)'!$C$71,'Sheet1 (2)'!$D$71*('Sheet1 (2)'!$D$72-crack_s_index)/'Sheet1 (2)'!$D$72)))) -> 5 | AW10: =IF(IF(D10='Sheet1 (2)'!$C$69,'Sheet1 (2)'!$D$69*('Sheet1 (2)'!$D$72-crack_t_index)/'Sheet1 (2)'!$D$72,IF(shee2!D10='Sheet1 (2)'!$C$70,'Sheet1 (2)'!$D$70*('Sheet1 (2)'!$D$72-crack_t_index)/'Sheet1 (2)'!$D$72,IF(shee2!D10='Sheet1 (2)'!$C$71,'Sheet1 (2)'!$D$71*('Sheet1 (2)'!$D$72-crack_t_index)/'Sheet1 (2)'!$D$72)))<0,0,IF(D10='Sheet1 (2)'!$C$69,'Sheet1 (2)'!$D$69*('Sheet1 (2)'!$D$72-crack_t_index)/'Sheet1 (2)'!$D$72,IF(shee2!D10='Sheet1 (2)'!$C$70,'Sheet1 (2)'!$D$70*('Sheet1 (2)'!$D$72-crack_t_index)/'Sheet1 (2)'!$D$72,IF(shee2!D10='Sheet1 (2)'!$C$71,'Sheet1 (2)'!$D$71*('Sheet1 (2)'!$D$72-crack_t_index)/'Sheet1 (2)'!$D$72)))) -> 5 | AX10: =IF(IF(D10='Sheet1 (2)'!$C$69,'Sheet1 (2)'!$D$69*('Sheet1 (2)'!$D$72-rave_index)/'Sheet1 (2)'!$D$72,IF(shee2!D10='Sheet1 (2)'!$C$70,'Sheet1 (2)'!$D$70*('Sheet1 (2)'!$D$72-rave_index)/'Sheet1 (2)'!$D$72,IF(shee2!D10='Sheet1 (2)'!$C$71,'Sheet1 (2)'!$D$71*('Sheet1 (2)'!$D$72-rave_index)/'Sheet1 (2)'!$D$72)))<0,0,IF(D10='Sheet1 (2)'!$C$69,'Sheet1 (2)'!$D$69*('Sheet1 (2)'!$D$72-rave_index)/'Sheet1 (2)'!$D$72,IF(shee2!D10='Sheet1 (2)'!$C$70,'Sheet1 (2)'!$D$70*('Sheet1 (2)'!$D$72-rave_index)/'Sheet1 (2)'!$D$72,IF(shee2!D10='Sheet1 (2)'!$C$71,'Sheet1 (2)'!$D$71*('Sheet1 (2)'!$D$72-rave_index)/'Sheet1 (2)'!$D$72)))) -> 0.3125 | AY10: =IF(IF(D10='Sheet1 (2)'!$C$69,'Sheet1 (2)'!$D$69*('Sheet1 (2)'!$D$72-rough_index)/'Sheet1 (2)'!$D$72,IF(shee2!D10='Sheet1 (2)'!$C$70,'Sheet1 (2)'!$D$70*('Sheet1 (2)'!$D$72-rough_index)/'Sheet1 (2)'!$D$72,IF(shee2!D10='Sheet1 (2)'!$C$71,'Sheet1 (2)'!$D$71*('Sheet1 (2)'!$D$72-rough_index)/'Sheet1 (2)'!$D$72)))<0,0,IF(D10='Sheet1 (2)'!$C$69,'Sheet1 (2)'!$D$69*('Sheet1 (2)'!$D$72-rough_index)/'Sheet1 (2)'!$D$72,IF(shee2!D10='Sheet1 (2)'!$C$70,'Sheet1 (2)'!$D$70*('Sheet1 (2)'!$D$72-rough_index)/'Sheet1 (2)'!$D$72,IF(shee2!D10='Sheet1 (2)'!$C$71,'Sheet1 (2)'!$D$71*('Sheet1 (2)'!$D$72-rough_index)/'Sheet1 (2)'!$D$72)))) -> 1.6666667 | AZ10: =+(AU10*'Sheet1 (2)'!$C$77)+(AV10*'Sheet1 (2)'!$C$78)+(AW10*'Sheet1 (2)'!$C$79)+(AX10*'Sheet1 (2)'!$C$80)+(AY10*'Sheet1 (2)'!$C$81) -> 3.53125 | BA10: =IF(AZ10="",$AH10,IF(AZ10>=4,"Good",IF(AZ10>=2.5,"Fair",IF(AZ10>=1,"Poor",IF(AZ10>=0,"Very Poor",""))))) -> Fair | BE10: =IF(D10='Sheet1 (2)'!$C$61,'Sheet1 (2)'!$D$61*(counts^2)+'Sheet1 (2)'!$G$61*counts+'Sheet1 (2)'!$J$61,IF(D10='Sheet1 (2)'!$C$62,'Sheet1 (2)'!$D$62*counts+'Sheet1 (2)'!$G$62,IF(D10='Sheet1 (2)'!$C$63,'Sheet1 (2)'!$D$63*counts+'Sheet1 (2)'!$G$63,IF(D10='Sheet1 (2)'!$C$64,'Sheet1 (2)'!$D$64*counts+'Sheet1 (2)'!$G$64)))) -> 2.0984129
A11: N-5 | B11: NB | C11: 151 | D11: A | E11: 8 | F11: 1 | G11: A | H11: 0.5 | I11: A | J11: x | K11: x | L11: =VLOOKUP(CONCATENATE(J11,K11),'Sheet1 (2)'!$J$6:$K$26,2,FALSE) -> 0 | M11: x | N11: x | O11: =VLOOKUP(CONCATENATE(M11,N11),'Sheet1 (2)'!$L$6:$M$26,2,FALSE) -> 0 | P11: x | Q11: x | R11: =VLOOKUP(CONCATENATE(P11,Q11),'Sheet1 (2)'!$N$6:$O$26,2,FALSE) -> 0 | S11: b | T11: b | U11: =VLOOKUP(CONCATENATE(S11,T11),'Sheet1 (2)'!$P$6:$Q$26,2,FALSE) -> 12.5 | V11: x | W11: x | X11: =VLOOKUP(CONCATENATE(V11,W11),'Sheet1 (2)'!$R$6:$S$26,2,FALSE) -> 0 | Y11: c | Z11: d | AA11: =VLOOKUP(CONCATENATE(Y11,Z11),'Sheet1 (2)'!$T$6:$U$26,2,FALSE) -> 56.25 | AB11: x | AC11: x | AD11: =VLOOKUP(CONCATENATE(AB11,AC11),'Sheet1 (2)'!$X$6:$Y$26,2,FALSE) -> 0 | AE11: b | AF11: e | AG11: =VLOOKUP(CONCATENATE(AE11,AF11),'Sheet1 (2)'!$Z$6:$AA$26,2,FALSE) -> 66 | AK11: N-5 | AL11: NB | AM11: =C11 -> 151 | AQ11: 3.5414035 | AS11: =LOOKUP(rufmkm,'Sheet1 (2)'!$V$62:$V$71,'Sheet1 (2)'!$W$62:$W$71) -> 40 | AU11: =IF(IF(D11='Sheet1 (2)'!$C$69,'Sheet1 (2)'!$D$69*('Sheet1 (2)'!$D$72-rut_index)/'Sheet1 (2)'!$D$72,IF(shee2!D11='Sheet1 (2)'!$C$70,'Sheet1 (2)'!$D$70*('Sheet1 (2)'!$D$72-rut_index)/'Sheet1 (2)'!$D$72,IF(shee2!D11='Sheet1 (2)'!$C$71,'Sheet1 (2)'!$D$71*('Sheet1 (2)'!$D$72-rut_index)/'Sheet1 (2)'!$D$72)))<0,0,IF(D11='Sheet1 (2)'!$C$69,'Sheet1 (2)'!$D$69*('Sheet1 (2)'!$D$72-rut_index)/'Sheet1 (2)'!$D$72,IF(shee2!D11='Sheet1 (2)'!$C$70,'Sheet1 (2)'!$D$70*('Sheet1 (2)'!$D$72-rut_index)/'Sheet1 (2)'!$D$72,IF(shee2!D11='Sheet1 (2)'!$C$71,'Sheet1 (2)'!$D$71*('Sheet1 (2)'!$D$72-rut_index)/'Sheet1 (2)'!$D$72)))) -> 5 | AV11: =IF(IF(D11='Sheet1 (2)'!$C$69,'Sheet1 (2)'!$D$69*('Sheet1 (2)'!$D$72-crack_s_index)/'Sheet1 (2)'!$D$72,IF(shee2!D11='Sheet1 (2)'!$C$70,'Sheet1 (2)'!$D$70*('Sheet1 (2)'!$D$72-crack_s_index)/'Sheet1 (2)'!$D$72,IF(shee2!D11='Sheet1 (2)'!$C$71,'Sheet1 (2)'!$D$71*('Sheet1 (2)'!$D$72-crack_s_index)/'Sheet1 (2)'!$D$72)))<0,0,IF(D11='Sheet1 (2)'!$C$69,'Sheet1 (2)'!$D$69*('Sheet1 (2)'!$D$72-crack_s_index)/'Sheet1 (2)'!$D$72,IF(shee2!D11='Sheet1 (2)'!$C$70,'Sheet1 (2)'!$D$70*('Sheet1 (2)'!$D$72-crack_s_index)/'Sheet1 (2)'!$D$72,IF(shee2!D11='Sheet1 (2)'!$C$71,'Sheet1 (2)'!$D$71*('Sheet1 (2)'!$D$72-crack_s_index)/'Sheet1 (2)'!$D$72)))) -> 5 | AW11: =IF(IF(D11='Sheet1 (2)'!$C$69,'Sheet1 (2)'!$D$69*('Sheet1 (2)'!$D$72-crack_t_index)/'Sheet1 (2)'!$D$72,IF(shee2!D11='Sheet1 (2)'!$C$70,'Sheet1 (2)'!$D$70*('Sheet1 (2)'!$D$72-crack_t_index)/'Sheet1 (2)'!$D$72,IF(shee2!D11='Sheet1 (2)'!$C$71,'Sheet1 (2)'!$D$71*('Sheet1 (2)'!$D$72-crack_t_index)/'Sheet1 (2)'!$D$72)))<0,0,IF(D11='Sheet1 (2)'!$C$69,'Sheet1 (2)'!$D$69*('Sheet1 (2)'!$D$72-crack_t_index)/'Sheet1 (2)'!$D$72,IF(shee2!D11='Sheet1 (2)'!$C$70,'Sheet1 (2)'!$D$70*('Sheet1 (2)'!$D$72-crack_t_index)/'Sheet1 (2)'!$D$72,IF(shee2!D11='Sheet1 (2)'!$C$71,'Sheet1 (2)'!$D$71*('Sheet1 (2)'!$D$72-crack_t_index)/'Sheet1 (2)'!$D$72)))) -> 5 | AX11: =IF(IF(D11='Sheet1 (2)'!$C$69,'Sheet1 (2)'!$D$69*('Sheet1 (2)'!$D$72-rave_index)/'Sheet1 (2)'!$D$72,IF(shee2!D11='Sheet1 (2)'!$C$70,'Sheet1 (2)'!$D$70*('Sheet1 (2)'!$D$72-rave_index)/'Sheet1 (2)'!$D$72,IF(shee2!D11='Sheet1 (2)'!$C$71,'Sheet1 (2)'!$D$71*('Sheet1 (2)'!$D$72-rave_index)/'Sheet1 (2)'!$D$72)))<0,0,IF(D11='Sheet1 (2)'!$C$69,'Sheet1 (2)'!$D$69*('Sheet1 (2)'!$D$72-rave_index)/'Sheet1 (2)'!$D$72,IF(shee2!D11='Sheet1 (2)'!$C$70,'Sheet1 (2)'!$D$70*('Sheet1 (2)'!$D$72-rave_index)/'Sheet1 (2)'!$D$72,IF(shee2!D11='Sheet1 (2)'!$C$71,'Sheet1 (2)'!$D$71*('Sheet1 (2)'!$D$72-rave_index)/'Sheet1 (2)'!$D$72)))) -> 0.3125 | AY11: =IF(IF(D11='Sheet1 (2)'!$C$69,'Sheet1 (2)'!$D$69*('Sheet1 (2)'!$D$72-rough_index)/'Sheet1 (2)'!$D$72,IF(shee2!D11='Sheet1 (2)'!$C$70,'Sheet1 (2)'!$D$70*('Sheet1 (2)'!$D$72-rough_index)/'Sheet1 (2)'!$D$72,IF(shee2!D11='Sheet1 (2)'!$C$71,'Sheet1 (2)'!$D$71*('Sheet1 (2)'!$D$72-rough_index)/'Sheet1 (2)'!$D$72)))<0,0,IF(D11='Sheet1 (2)'!$C$69,'Sheet1 (2)'!$D$69*('Sheet1 (2)'!$D$72-rough_index)/'Sheet1 (2)'!$D$72,IF(shee2!D11='Sheet1 (2)'!$C$70,'Sheet1 (2)'!$D$70*('Sheet1 (2)'!$D$72-rough_index)/'Sheet1 (2)'!$D$72,IF(shee2!D11='Sheet1 (2)'!$C$71,'Sheet1 (2)'!$D$71*('Sheet1 (2)'!$D$72-rough_index)/'Sheet1 (2)'!$D$72)))) -> 1.6666667 | AZ11: =+(AU11*'Sheet1 (2)'!$C$77)+(AV11*'Sheet1 (2)'!$C$78)+(AW11*'Sheet1 (2)'!$C$79)+(AX11*'Sheet1 (2)'!$C$80)+(AY11*'Sheet1 (2)'!$C$81) -> 3.53125 | BA11: =IF(AZ11="",$AH11,IF(AZ11>=4,"Good",IF(AZ11>=2.5,"Fair",IF(AZ11>=1,"Poor",IF(AZ11>=0,"Very Poor",""))))) -> Fair | BE11: =IF(D11='Sheet1 (2)'!$C$61,'Sheet1 (2)'!$D$61*(counts^2)+'Sheet1 (2)'!$G$61*counts+'Sheet1 (2)'!$J$61,IF(D11='Sheet1 (2)'!$C$62,'Sheet1 (2)'!$D$62*counts+'Sheet1 (2)'!$G$62,IF(D11='Sheet1 (2)'!$C$63,'Sheet1 (2)'!$D$63*counts+'Sheet1 (2)'!$G$63,IF(D11='Sheet1 (2)'!$C$64,'Sheet1 (2)'!$D$64*counts+'Sheet1 (2)'!$G$64)))) -> 2.0984129
A12: N-5 | B12: NB | C12: 152 | D12: A | E12: 8 | F12: 1 | G12: A | H12: 0.5 | I12: A | J12: x | K12: x | L12: =VLOOKUP(CONCATENATE(J12,K12),'Sheet1 (2)'!$J$6:$K$26,2,FALSE) -> 0 | M12: x | N12: x | O12: =VLOOKUP(CONCATENATE(M12,N12),'Sheet1 (2)'!$L$6:$M$26,2,FALSE) -> 0 | P12: x | Q12: x | R12: =VLOOKUP(CONCATENATE(P12,Q12),'Sheet1 (2)'!$N$6:$O$26,2,FALSE) -> 0 | S12: x | T12: x | U12: =VLOOKUP(CONCATENATE(S12,T12),'Sheet1 (2)'!$P$6:$Q$26,2,FALSE) -> 0 | V12: a | W12: e | X12: =VLOOKUP(CONCATENATE(V12,W12),'Sheet1 (2)'!$R$6:$S$26,2,FALSE) -> 25 | Y12: d | Z12: e | AA12: =VLOOKUP(CONCATENATE(Y12,Z12),'Sheet1 (2)'!$T$6:$U$26,2,FALSE) -> 100 | AB12: x | AC12: x | AD12: =VLOOKUP(CONCATENATE(AB12,AC12),'Sheet1 (2)'!$X$6:$Y$26,2,FALSE) -> 0 | AE12: b | AF12: e | AG12: =VLOOKUP(CONCATENATE(AE12,AF12),'Sheet1 (2)'!$Z$6:$AA$26,2,FALSE) -> 66 | AK12: N-5 | AL12: NB | AM12: =C12 -> 152 | AO12: Bridge | AQ12: 6.0108821 | AS12: =LOOKUP(rufmkm,'Sheet1 (2)'!$V$62:$V$71,'Sheet1 (2)'!$W$62:$W$71) -> 70 | AU12: =IF(IF(D12='Sheet1 (2)'!$C$69,'Sheet1 (2)'!$D$69*('Sheet1 (2)'!$D$72-rut_index)/'Sheet1 (2)'!$D$72,IF(shee2!D12='Sheet1 (2)'!$C$70,'Sheet1 (2)'!$D$70*('Sheet1 (2)'!$D$72-rut_index)/'Sheet1 (2)'!$D$72,IF(shee2!D12='Sheet1 (2)'!$C$71,'Sheet1 (2)'!$D$71*('Sheet1 (2)'!$D$72-rut_index)/'Sheet1 (2)'!$D$72)))<0,0,IF(D12='Sheet1 (2)'!$C$69,'Sheet1 (2)'!$D$69*('Sheet1 (2)'!$D$72-rut_index)/'Sheet1 (2)'!$D$72,IF(shee2!D12='Sheet1 (2)'!$C$70,'Sheet1 (2)'!$D$70*('Sheet1 (2)'!$D$72-rut_index)/'Sheet1 (2)'!$D$72,IF(shee2!D12='Sheet1 (2)'!$C$71,'Sheet1 (2)'!$D$71*('Sheet1 (2)'!$D$72-rut_index)/'Sheet1 (2)'!$D$72)))) -> 5 | AV12: =IF(IF(D12='Sheet1 (2)'!$C$69,'Sheet1 (2)'!$D$69*('Sheet1 (2)'!$D$72-crack_s_index)/'Sheet1 (2)'!$D$72,IF(shee2!D12='Sheet1 (2)'!$C$70,'Sheet1 (2)'!$D$70*('Sheet1 (2)'!$D$72-crack_s_index)/'Sheet1 (2)'!$D$72,IF(shee2!D12='Sheet1 (2)'!$C$71,'Sheet1 (2)'!$D$71*('Sheet1 (2)'!$D$72-crack_s_index)/'Sheet1 (2)'!$D$72)))<0,0,IF(D12='Sheet1 (2)'!$C$69,'Sheet1 (2)'!$D$69*('Sheet1 (2)'!$D$72-crack_s_index)/'Sheet1 (2)'!$D$72,IF(shee2!D12='Sheet1 (2)'!$C$70,'Sheet1 (2)'!$D$70*('Sheet1 (2)'!$D$72-crack_s_index)/'Sheet1 (2)'!$D$72,IF(shee2!D12='Sheet1 (2)'!$C$71,'Sheet1 (2)'!$D$71*('Sheet1 (2)'!$D$72-crack_s_index)/'Sheet1 (2)'!$D$72)))) -> 5 | AW12: =IF(IF(D12='Sheet1 (2)'!$C$69,'Sheet1 (2)'!$D$69*('Sheet1 (2)'!$D$72-crack_t_index)/'Sheet1 (2)'!$D$72,IF(shee2!D12='Sheet1 (2)'!$C$70,'Sheet1 (2)'!$D$70*('Sheet1 (2)'!$D$72-crack_t_index)/'Sheet1 (2)'!$D$72,IF(shee2!D12='Sheet1 (2)'!$C$71,'Sheet1 (2)'!$D$71*('Sheet1 (2)'!$D$72-crack_t_index)/'Sheet1 (2)'!$D$72)))<0,0,IF(D12='Sheet1 (2)'!$C$69,'Sheet1 (2)'!$D$69*('Sheet1 (2)'!$D$72-crack_t_index)/'Sheet1 (2)'!$D$72,IF(shee2!D12='Sheet1 (2)'!$C$70,'Sheet1 (2)'!$D$70*('Sheet1 (2)'!$D$72-crack_t_index)/'Sheet1 (2)'!$D$72,IF(shee2!D12='Sheet1 (2)'!$C$71,'Sheet1 (2)'!$D$71*('Sheet1 (2)'!$D$72-crack_t_index)/'Sheet1 (2)'!$D$72)))) -> 5 | AX12: =IF(IF(D12='Sheet1 (2)'!$C$69,'Sheet1 (2)'!$D$69*('Sheet1 (2)'!$D$72-rave_index)/'Sheet1 (2)'!$D$72,IF(shee2!D12='Sheet1 (2)'!$C$70,'Sheet1 (2)'!$D$70*('Sheet1 (2)'!$D$72-rave_index)/'Sheet1 (2)'!$D$72,IF(shee2!D12='Sheet1 (2)'!$C$71,'Sheet1 (2)'!$D$71*('Sheet1 (2)'!$D$72-rave_index)/'Sheet1 (2)'!$D$72)))<0,0,IF(D12='Sheet1 (2)'!$C$69,'Sheet1 (2)'!$D$69*('Sheet1 (2)'!$D$72-rave_index)/'Sheet1 (2)'!$D$72,IF(shee2!D12='Sheet1 (2)'!$C$70,'Sheet1 (2)'!$D$70*('Sheet1 (2)'!$D$72-rave_index)/'Sheet1 (2)'!$D$72,IF(shee2!D12='Sheet1 (2)'!$C$71,'Sheet1 (2)'!$D$71*('Sheet1 (2)'!$D$72-rave_index)/'Sheet1 (2)'!$D$72)))) -> 0 | AY12: =IF(IF(D12='Sheet1 (2)'!$C$69,'Sheet1 (2)'!$D$69*('Sheet1 (2)'!$D$72-rough_index)/'Sheet1 (2)'!$D$72,IF(shee2!D12='Sheet1 (2)'!$C$70,'Sheet1 (2)'!$D$70*('Sheet1 (2)'!$D$72-rough_index)/'Sheet1 (2)'!$D$72,IF(shee2!D12='Sheet1 (2)'!$C$71,'Sheet1 (2)'!$D$71*('Sheet1 (2)'!$D$72-rough_index)/'Sheet1 (2)'!$D$72)))<0,0,IF(D12='Sheet1 (2)'!$C$69,'Sheet1 (2)'!$D$69*('Sheet1 (2)'!$D$72-rough_index)/'Sheet1 (2)'!$D$72,IF(shee2!D12='Sheet1 (2)'!$C$70,'Sheet1 (2)'!$D$70*('Sheet1 (2)'!$D$72-rough_index)/'Sheet1 (2)'!$D$72,IF(shee2!D12='Sheet1 (2)'!$C$71,'Sheet1 (2)'!$D$71*('Sheet1 (2)'!$D$72-rough_index)/'Sheet1 (2)'!$D$72)))) -> 0 | AZ12: =+(AU12*'Sheet1 (2)'!$C$77)+(AV12*'Sheet1 (2)'!$C$78)+(AW12*'Sheet1 (2)'!$C$79)+(AX12*'Sheet1 (2)'!$C$80)+(AY12*'Sheet1 (2)'!$C$81) -> 3 | BA12: =IF(AZ12="",$AH12,IF(AZ12>=4,"Good",IF(AZ12>=2.5,"Fair",IF(AZ12>=1,"Poor",IF(AZ12>=0,"Very Poor",""))))) -> Fair | BE12: =IF(D12='Sheet1 (2)'!$C$61,'Sheet1 (2)'!$D$61*(counts^2)+'Sheet1 (2)'!$G$61*counts+'Sheet1 (2)'!$J$61,IF(D12='Sheet1 (2)'!$C$62,'Sheet1 (2)'!$D$62*counts+'Sheet1 (2)'!$G$62,IF(D12='Sheet1 (2)'!$C$63,'Sheet1 (2)'!$D$63*counts+'Sheet1 (2)'!$G$63,IF(D12='Sheet1 (2)'!$C$64,'Sheet1 (2)'!$D$64*counts+'Sheet1 (2)'!$G$64)))) -> 2.0984129
A13: N-5 | B13: NB | C13: 153 | D13: A | E13: 8 | F13: 1 | G13: A | H13: 0.5 | I13: A | J13: x | K13: x | L13: =VLOOKUP(CONCATENATE(J13,K13),'Sheet1 (2)'!$J$6:$K$26,2,FALSE) -> 0 | M13: d | N13: a | O13: =VLOOKUP(CONCATENATE(M13,N13),'Sheet1 (2)'!$L$6:$M$26,2,FALSE) -> 10 | P13: x | Q13: x | R13: =VLOOKUP(CONCATENATE(P13,Q13),'Sheet1 (2)'!$N$6:$O$26,2,FALSE) -> 0 | S13: x | T13: x | U13: =VLOOKUP(CONCATENATE(S13,T13),'Sheet1 (2)'!$P$6:$Q$26,2,FALSE) -> 0 | V13: x | W13: x | X13: =VLOOKUP(CONCATENATE(V13,W13),'Sheet1 (2)'!$R$6:$S$26,2,FALSE) -> 0 | Y13: x | Z13: x | AA13: =VLOOKUP(CONCATENATE(Y13,Z13),'Sheet1 (2)'!$T$6:$U$26,2,FALSE) -> 0 | AB13: x | AC13: x | AD13: =VLOOKUP(CONCATENATE(AB13,AC13),'Sheet1 (2)'!$X$6:$Y$26,2,FALSE) -> 0 | AE13: b | AF13: e | AG13: =VLOOKUP(CONCATENATE(AE13,AF13),'Sheet1 (2)'!$Z$6:$AA$26,2,FALSE) -> 66 | AK13: N-5 | AL13: NB | AM13: =C13 -> 153 | AO13: BRKR | AQ13: 8.0365515 | AS13: =LOOKUP(rufmkm,'Sheet1 (2)'!$V$62:$V$71,'Sheet1 (2)'!$W$62:$W$71) -> 90 | AU13: =IF(IF(D13='Sheet1 (2)'!$C$69,'Sheet1 (2)'!$D$69*('Sheet1 (2)'!$D$72-rut_index)/'Sheet1 (2)'!$D$72,IF(shee2!D13='Sheet1 (2)'!$C$70,'Sheet1 (2)'!$D$70*('Sheet1 (2)'!$D$72-rut_index)/'Sheet1 (2)'!$D$72,IF(shee2!D13='Sheet1 (2)'!$C$71,'Sheet1 (2)'!$D$71*('Sheet1 (2)'!$D$72-rut_index)/'Sheet1 (2)'!$D$72)))<0,0,IF(D13='Sheet1 (2)'!$C$69,'Sheet1 (2)'!$D$69*('Sheet1 (2)'!$D$72-rut_index)/'Sheet1 (2)'!$D$72,IF(shee2!D13='Sheet1 (2)'!$C$70,'Sheet1 (2)'!$D$70*('Sheet1 (2)'!$D$72-rut_index)/'Sheet1 (2)'!$D$72,IF(shee2!D13='Sheet1 (2)'!$C$71,'Sheet1 (2)'!$D$71*('Sheet1 (2)'!$D$72-rut_index)/'Sheet1 (2)'!$D$72)))) -> 5 | AV13: =IF(IF(D13='Sheet1 (2)'!$C$69,'Sheet1 (2)'!$D$69*('Sheet1 (2)'!$D$72-crack_s_index)/'Sheet1 (2)'!$D$72,IF(shee2!D13='Sheet1 (2)'!$C$70,'Sheet1 (2)'!$D$70*('Sheet1 (2)'!$D$72-crack_s_index)/'Sheet1 (2)'!$D$72,IF(shee2!D13='Sheet1 (2)'!$C$71,'Sheet1 (2)'!$D$71*('Sheet1 (2)'!$D$72-crack_s_index)/'Sheet1 (2)'!$D$72)))<0,0,IF(D13='Sheet1 (2)'!$C$69,'Sheet1 (2)'!$D$69*('Sheet1 (2)'!$D$72-crack_s_index)/'Sheet1 (2)'!$D$72,IF(shee2!D13='Sheet1 (2)'!$C$70,'Sheet1 (2)'!$D$70*('Sheet1 (2)'!$D$72-crack_s_index)/'Sheet1 (2)'!$D$72,IF(shee2!D13='Sheet1 (2)'!$C$71,'Sheet1 (2)'!$D$71*('Sheet1 (2)'!$D$72-crack_s_index)/'Sheet1 (2)'!$D$72)))) -> 4.1666667 | AW13: =IF(IF(D13='Sheet1 (2)'!$C$69,'Sheet1 (2)'!$D$69*('Sheet1 (2)'!$D$72-crack_t_index)/'Sheet1 (2)'!$D$72,IF(shee2!D13='Sheet1 (2)'!$C$70,'Sheet1 (2)'!$D$70*('Sheet1 (2)'!$D$72-crack_t_index)/'Sheet1 (2)'!$D$72,IF(shee2!D13='Sheet1 (2)'!$C$71,'Sheet1 (2)'!$D$71*('Sheet1 (2)'!$D$72-crack_t_index)/'Sheet1 (2)'!$D$72)))<0,0,IF(D13='Sheet1 (2)'!$C$69,'Sheet1 (2)'!$D$69*('Sheet1 (2)'!$D$72-crack_t_index)/'Sheet1 (2)'!$D$72,IF(shee2!D13='Sheet1 (2)'!$C$70,'Sheet1 (2)'!$D$70*('Sheet1 (2)'!$D$72-crack_t_index)/'Sheet1 (2)'!$D$72,IF(shee2!D13='Sheet1 (2)'!$C$71,'Sheet1 (2)'!$D$71*('Sheet1 (2)'!$D$72-crack_t_index)/'Sheet1 (2)'!$D$72)))) -> 5 | AX13: =IF(IF(D13='Sheet1 (2)'!$C$69,'Sheet1 (2)'!$D$69*('Sheet1 (2)'!$D$72-rave_index)/'Sheet1 (2)'!$D$72,IF(shee2!D13='Sheet1 (2)'!$C$70,'Sheet1 (2)'!$D$70*('Sheet1 (2)'!$D$72-rave_index)/'Sheet1 (2)'!$D$72,IF(shee2!D13='Sheet1 (2)'!$C$71,'Sheet1 (2)'!$D$71*('Sheet1 (2)'!$D$72-rave_index)/'Sheet1 (2)'!$D$72)))<0,0,IF(D13='Sheet1 (2)'!$C$69,'Sheet1 (2)'!$D$69*('Sheet1 (2)'!$D$72-rave_index)/'Sheet1 (2)'!$D$72,IF(shee2!D13='Sheet1 (2)'!$C$70,'Sheet1 (2)'!$D$70*('Sheet1 (2)'!$D$72-rave_index)/'Sheet1 (2)'!$D$72,IF(shee2!D13='Sheet1 (2)'!$C$71,'Sheet1 (2)'!$D$71*('Sheet1 (2)'!$D$72-rave_index)/'Sheet1 (2)'!$D$72)))) -> 5 | AY13: =IF(IF(D13='Sheet1 (2)'!$C$69,'Sheet1 (2)'!$D$69*('Sheet1 (2)'!$D$72-rough_index)/'Sheet1 (2)'!$D$72,IF(shee2!D13='Sheet1 (2)'!$C$70,'Sheet1 (2)'!$D$70*('Sheet1 (2)'!$D$72-rough_index)/'Sheet1 (2)'!$D$72,IF(shee2!D13='Sheet1 (2)'!$C$71,'Sheet1 (2)'!$D$71*('Sheet1 (2)'!$D$72-rough_index)/'Sheet1 (2)'!$D$72)))<0,0,IF(D13='Sheet1 (2)'!$C$69,'Sheet1 (2)'!$D$69*('Sheet1 (2)'!$D$72-rough_index)/'Sheet1 (2)'!$D$72,IF(shee2!D13='Sheet1 (2)'!$C$70,'Sheet1 (2)'!$D$70*('Sheet1 (2)'!$D$72-rough_index)/'Sheet1 (2)'!$D$72,IF(shee2!D13='Sheet1 (2)'!$C$71,'Sheet1 (2)'!$D$71*('Sheet1 (2)'!$D$72-rough_index)/'Sheet1 (2)'!$D$72)))) -> 0 | AZ13: =+(AU13*'Sheet1 (2)'!$C$77)+(AV13*'Sheet1 (2)'!$C$78)+(AW13*'Sheet1 (2)'!$C$79)+(AX13*'Sheet1 (2)'!$C$80)+(AY13*'Sheet1 (2)'!$C$81) -> 3.2 | BA13: =IF(AZ13="",$AH13,IF(AZ13>=4,"Good",IF(AZ13>=2.5,"Fair",IF(AZ13>=1,"Poor",IF(AZ13>=0,"Very Poor",""))))) -> Fair | BE13: =IF(D13='Sheet1 (2)'!$C$61,'Sheet1 (2)'!$D$61*(counts^2)+'Sheet1 (2)'!$G$61*counts+'Sheet1 (2)'!$J$61,IF(D13='Sheet1 (2)'!$C$62,'Sheet1 (2)'!$D$62*counts+'Sheet1 (2)'!$G$62,IF(D13='Sheet1 (2)'!$C$63,'Sheet1 (2)'!$D$63*counts+'Sheet1 (2)'!$G$63,IF(D13='Sheet1 (2)'!$C$64,'Sheet1 (2)'!$D$64*counts+'Sheet1 (2)'!$G$64)))) -> 2.0984129
A14: N-5 | B14: NB | C14: 154 | D14: A | E14: 8 | F14: 1 | G14: A | H14: 0.5 | I14: A | J14: x | K14: x | L14: =VLOOKUP(CONCATENATE(J14,K14),'Sheet1 (2)'!$J$6:$K$26,2,FALSE) -> 0 | M14: d | N14: a | O14: =VLOOKUP(CONCATENATE(M14,N14),'Sheet1 (2)'!$L$6:$M$26,2,FALSE) -> 10 | P14: d | Q14: a | R14: =VLOOKUP(CONCATENATE(P14,Q14),'Sheet1 (2)'!$N$6:$O$26,2,FALSE) -> 10 | S14: x | T14: x | U14: =VLOOKUP(CONCATENATE(S14,T14),'Sheet1 (2)'!$P$6:$Q$26,2,FALSE) -> 0 | V14: a | W14: e | X14: =VLOOKUP(CONCATENATE(V14,W14),'Sheet1 (2)'!$R$6:$S$26,2,FALSE) -> 25 | Y14: d | Z14: b | AA14: =VLOOKUP(CONCATENATE(Y14,Z14),'Sheet1 (2)'!$T$6:$U$26,2,FALSE) -> 25 | AB14: x | AC14: x | AD14: =VLOOKUP(CONCATENATE(AB14,AC14),'Sheet1 (2)'!$X$6:$Y$26,2,FALSE) -> 0 | AE14: b | AF14: e | AG14: =VLOOKUP(CONCATENATE(AE14,AF14),'Sheet1 (2)'!$Z$6:$AA$26,2,FALSE) -> 66 | AK14: N-5 | AL14: NB | AM14: =C14 -> 154 | AQ14: 6.0619637 | AS14: =LOOKUP(rufmkm,'Sheet1 (2)'!$V$62:$V$71,'Sheet1 (2)'!$W$62:$W$71) -> 70 | AU14: =IF(IF(D14='Sheet1 (2)'!$C$69,'Sheet1 (2)'!$D$69*('Sheet1 (2)'!$D$72-rut_index)/'Sheet1 (2)'!$D$72,IF(shee2!D14='Sheet1 (2)'!$C$70,'Sheet1 (2)'!$D$70*('Sheet1 (2)'!$D$72-rut_index)/'Sheet1 (2)'!$D$72,IF(shee2!D14='Sheet1 (2)'!$C$71,'Sheet1 (2)'!$D$71*('Sheet1 (2)'!$D$72-rut_index)/'Sheet1 (2)'!$D$72)))<0,0,IF(D14='Sheet1 (2)'!$C$69,'Sheet1 (2)'!$D$69*('Sheet1 (2)'!$D$72-rut_index)/'Sheet1 (2)'!$D$72,IF(shee2!D14='Sheet1 (2)'!$C$70,'Sheet1 (2)'!$D$70*('Sheet1 (2)'!$D$72-rut_index)/'Sheet1 (2)'!$D$72,IF(shee2!D14='Sheet1 (2)'!$C$71,'Sheet1 (2)'!$D$71*('Sheet1 (2)'!$D$72-rut_index)/'Sheet1 (2)'!$D$72)))) -> 5 | AV14: =IF(IF(D14='Sheet1 (2)'!$C$69,'Sheet1 (2)'!$D$69*('Sheet1 (2)'!$D$72-crack_s_index)/'Sheet1 (2)'!$D$72,IF(shee2!D14='Sheet1 (2)'!$C$70,'Sheet1 (2)'!$D$70*('Sheet1 (2)'!$D$72-crack_s_index)/'Sheet1 (2)'!$D$72,IF(shee2!D14='Sheet1 (2)'!$C$71,'Sheet1 (2)'!$D$71*('Sheet1 (2)'!$D$72-crack_s_index)/'Sheet1 (2)'!$D$72)))<0,0,IF(D14='Sheet1 (2)'!$C$69,'Sheet1 (2)'!$D$69*('Sheet1 (2)'!$D$72-crack_s_index)/'Sheet1 (2)'!$D$72,IF(shee2!D14='Sheet1 (2)'!$C$70,'Sheet1 (2)'!$D$70*('Sheet1 (2)'!$D$72-crack_s_index)/'Sheet1 (2)'!$D$72,IF(shee2!D14='Sheet1 (2)'!$C$71,'Sheet1 (2)'!$D$71*('Sheet1 (2)'!$D$72-crack_s_index)/'Sheet1 (2)'!$D$72)))) -> 4.1666667 | AW14: =IF(IF(D14='Sheet1 (2)'!$C$69,'Sheet1 (2)'!$D$69*('Sheet1 (2)'!$D$72-crack_t_index)/'Sheet1 (2)'!$D$72,IF(shee2!D14='Sheet1 (2)'!$C$70,'Sheet1 (2)'!$D$70*('Sheet1 (2)'!$D$72-crack_t_index)/'Sheet1 (2)'!$D$72,IF(shee2!D14='Sheet1 (2)'!$C$71,'Sheet1 (2)'!$D$71*('Sheet1 (2)'!$D$72-crack_t_index)/'Sheet1 (2)'!$D$72)))<0,0,IF(D14='Sheet1 (2)'!$C$69,'Sheet1 (2)'!$D$69*('Sheet1 (2)'!$D$72-crack_t_index)/'Sheet1 (2)'!$D$72,IF(shee2!D14='Sheet1 (2)'!$C$70,'Sheet1 (2)'!$D$70*('Sheet1 (2)'!$D$72-crack_t_index)/'Sheet1 (2)'!$D$72,IF(shee2!D14='Sheet1 (2)'!$C$71,'Sheet1 (2)'!$D$71*('Sheet1 (2)'!$D$72-crack_t_index)/'Sheet1 (2)'!$D$72)))) -> 4.1666667 | AX14: =IF(IF(D14='Sheet1 (2)'!$C$69,'Sheet1 (2)'!$D$69*('Sheet1 (2)'!$D$72-rave_index)/'Sheet1 (2)'!$D$72,IF(shee2!D14='Sheet1 (2)'!$C$70,'Sheet1 (2)'!$D$70*('Sheet1 (2)'!$D$72-rave_index)/'Sheet1 (2)'!$D$72,IF(shee2!D14='Sheet1 (2)'!$C$71,'Sheet1 (2)'!$D$71*('Sheet1 (2)'!$D$72-rave_index)/'Sheet1 (2)'!$D$72)))<0,0,IF(D14='Sheet1 (2)'!$C$69,'Sheet1 (2)'!$D$69*('Sheet1 (2)'!$D$72-rave_index)/'Sheet1 (2)'!$D$72,IF(shee2!D14='Sheet1 (2)'!$C$70,'Sheet1 (2)'!$D$70*('Sheet1 (2)'!$D$72-rave_index)/'Sheet1 (2)'!$D$72,IF(shee2!D14='Sheet1 (2)'!$C$71,'Sheet1 (2)'!$D$71*('Sheet1 (2)'!$D$72-rave_index)/'Sheet1 (2)'!$D$72)))) -> 2.9166667 | AY14: =IF(IF(D14='Sheet1 (2)'!$C$69,'Sheet1 (2)'!$D$69*('Sheet1 (2)'!$D$72-rough_index)/'Sheet1 (2)'!$D$72,IF(shee2!D14='Sheet1 (2)'!$C$70,'Sheet1 (2)'!$D$70*('Sheet1 (2)'!$D$72-rough_index)/'Sheet1 (2)'!$D$72,IF(shee2!D14='Sheet1 (2)'!$C$71,'Sheet1 (2)'!$D$71*('Sheet1 (2)'!$D$72-rough_index)/'Sheet1 (2)'!$D$72)))<0,0,IF(D14='Sheet1 (2)'!$C$69,'Sheet1 (2)'!$D$69*('Sheet1 (2)'!$D$72-rough_index)/'Sheet1 (2)'!$D$72,IF(shee2!D14='Sheet1 (2)'!$C$70,'Sheet1 (2)'!$D$70*('Sheet1 (2)'!$D$72-rough_index)/'Sheet1 (2)'!$D$72,IF(shee2!D14='Sheet1 (2)'!$C$71,'Sheet1 (2)'!$D$71*('Sheet1 (2)'!$D$72-rough_index)/'Sheet1 (2)'!$D$72)))) -> 0 | AZ14: =+(AU14*'Sheet1 (2)'!$C$77)+(AV14*'Sheet1 (2)'!$C$78)+(AW14*'Sheet1 (2)'!$C$79)+(AX14*'Sheet1 (2)'!$C$80)+(AY14*'Sheet1 (2)'!$C$81) -> 2.9583333 | BA14: =IF(AZ14="",$AH14,IF(AZ14>=4,"Good",IF(AZ14>=2.5,"Fair",IF(AZ14>=1,"Poor",IF(AZ14>=0,"Very Poor",""))))) -> Fair | BE14: =IF(D14='Sheet1 (2)'!$C$61,'Sheet1 (2)'!$D$61*(counts^2)+'Sheet1 (2)'!$G$61*counts+'Sheet1 (2)'!$J$61,IF(D14='Sheet1 (2)'!$C$62,'Sheet1 (2)'!$D$62*counts+'Sheet1 (2)'!$G$62,IF(D14='Sheet1 (2)'!$C$63,'Sheet1 (2)'!$D$63*counts+'Sheet1 (2)'!$G$63,IF(D14='Sheet1 (2)'!$C$64,'Sheet1 (2)'!$D$64*counts+'Sheet1 (2)'!$G$64)))) -> 2.0984129
A15: N-5 | B15: NB | C15: 155 | D15: A | E15: 8 | F15: 1 | G15: A | H15: 0.5 | I15: A | J15: x | K15: x | L15: =VLOOKUP(CONCATENATE(J15,K15),'Sheet1 (2)'!$J$6:$K$26,2,FALSE) -> 0 | M15: x | N15: x | O15: =VLOOKUP(CONCATENATE(M15,N15),'Sheet1 (2)'!$L$6:$M$26,2,FALSE) -> 0 | P15: d | Q15: a | R15: =VLOOKUP(CONCATENATE(P15,Q15),'Sheet1 (2)'!$N$6:$O$26,2,FALSE) -> 10 | S15: d | T15: a | U15: =VLOOKUP(CONCATENATE(S15,T15),'Sheet1 (2)'!$P$6:$Q$26,2,FALSE) -> 10 | V15: a | W15: e | X15: =VLOOKUP(CONCATENATE(V15,W15),'Sheet1 (2)'!$R$6:$S$26,2,FALSE) -> 25 | Y15: d | Z15: b | AA15: =VLOOKUP(CONCATENATE(Y15,Z15),'Sheet1 (2)'!$T$6:$U$26,2,FALSE) -> 25 | AB15: x | AC15: x | AD15: =VLOOKUP(CONCATENATE(AB15,AC15),'Sheet1 (2)'!$X$6:$Y$26,2,FALSE) -> 0 | AE15: b | AF15: e | AG15: =VLOOKUP(CONCATENATE(AE15,AF15),'Sheet1 (2)'!$Z$6:$AA$26,2,FALSE) -> 66 | AK15: N-5 | AL15: NB | AM15: =C15 -> 155 | AQ15: 5.8711112 | AS15: =LOOKUP(rufmkm,'Sheet1 (2)'!$V$62:$V$71,'Sheet1 (2)'!$W$62:$W$71) -> 60 | AU15: =IF(IF(D15='Sheet1 (2)'!$C$69,'Sheet1 (2)'!$D$69*('Sheet1 (2)'!$D$72-rut_index)/'Sheet1 (2)'!$D$72,IF(shee2!D15='Sheet1 (2)'!$C$70,'Sheet1 (2)'!$D$70*('Sheet1 (2)'!$D$72-rut_index)/'Sheet1 (2)'!$D$72,IF(shee2!D15='Sheet1 (2)'!$C$71,'Sheet1 (2)'!$D$71*('Sheet1 (2)'!$D$72-rut_index)/'Sheet1 (2)'!$D$72)))<0,0,IF(D15='Sheet1 (2)'!$C$69,'Sheet1 (2)'!$D$69*('Sheet1 (2)'!$D$72-rut_index)/'Sheet1 (2)'!$D$72,IF(shee2!D15='Sheet1 (2)'!$C$70,'Sheet1 (2)'!$D$70*('Sheet1 (2)'!$D$72-rut_index)/'Sheet1 (2)'!$D$72,IF(shee2!D15='Sheet1 (2)'!$C$71,'Sheet1 (2)'!$D$71*('Sheet1 (2)'!$D$72-rut_index)/'Sheet1 (2)'!$D$72)))) -> 5 | AV15: =IF(IF(D15='Sheet1 (2)'!$C$69,'Sheet1 (2)'!$D$69*('Sheet1 (2)'!$D$72-crack_s_index)/'Sheet1 (2)'!$D$72,IF(shee2!D15='Sheet1 (2)'!$C$70,'Sheet1 (2)'!$D$70*('Sheet1 (2)'!$D$72-crack_s_index)/'Sheet1 (2)'!$D$72,IF(shee2!D15='Sheet1 (2)'!$C$71,'Sheet1 (2)'!$D$71*('Sheet1 (2)'!$D$72-crack_s_index)/'Sheet1 (2)'!$D$72)))<0,0,IF(D15='Sheet1 (2)'!$C$69,'Sheet1 (2)'!$D$69*('Sheet1 (2)'!$D$72-crack_s_index)/'Sheet1 (2)'!$D$72,IF(shee2!D15='Sheet1 (2)'!$C$70,'Sheet1 (2)'!$D$70*('Sheet1 (2)'!$D$72-crack_s_index)/'Sheet1 (2)'!$D$72,IF(shee2!D15='Sheet1 (2)'!$C$71,'Sheet1 (2)'!$D$71*('Sheet1 (2)'!$D$72-crack_s_index)/'Sheet1 (2)'!$D$72)))) -> 5 | AW15: =IF(IF(D15='Sheet1 (2)'!$C$69,'Sheet1 (2)'!$D$69*('Sheet1 (2)'!$D$72-crack_t_index)/'Sheet1 (2)'!$D$72,IF(shee2!D15='Sheet1 (2)'!$C$70,'Sheet1 (2)'!$D$70*('Sheet1 (2)'!$D$72-crack_t_index)/'Sheet1 (2)'!$D$72,IF(shee2!D15='Sheet1 (2)'!$C$71,'Sheet1 (2)'!$D$71*('Sheet1 (2)'!$D$72-crack_t_index)/'Sheet1 (2)'!$D$72)))<0,0,IF(D15='Sheet1 (2)'!$C$69,'Sheet1 (2)'!$D$69*('Sheet1 (2)'!$D$72-crack_t_index)/'Sheet1 (2)'!$D$72,IF(shee2!D15='Sheet1 (2)'!$C$70,'Sheet1 (2)'!$D$70*('Sheet1 (2)'!$D$72-crack_t_index)/'Sheet1 (2)'!$D$72,IF(shee2!D15='Sheet1 (2)'!$C$71,'Sheet1 (2)'!$D$71*('Sheet1 (2)'!$D$72-crack_t_index)/'Sheet1 (2)'!$D$72)))) -> 4.1666667 | AX15: =IF(IF(D15='Sheet1 (2)'!$C$69,'Sheet1 (2)'!$D$69*('Sheet1 (2)'!$D$72-rave_index)/'Sheet1 (2)'!$D$72,IF(shee2!D15='Sheet1 (2)'!$C$70,'Sheet1 (2)'!$D$70*('Sheet1 (2)'!$D$72-rave_index)/'Sheet1 (2)'!$D$72,IF(shee2!D15='Sheet1 (2)'!$C$71,'Sheet1 (2)'!$D$71*('Sheet1 (2)'!$D$72-rave_index)/'Sheet1 (2)'!$D$72)))<0,0,IF(D15='Sheet1 (2)'!$C$69,'Sheet1 (2)'!$D$69*('Sheet1 (2)'!$D$72-rave_index)/'Sheet1 (2)'!$D$72,IF(shee2!D15='Sheet1 (2)'!$C$70,'Sheet1 (2)'!$D$70*('Sheet1 (2)'!$D$72-rave_index)/'Sheet1 (2)'!$D$72,IF(shee2!D15='Sheet1 (2)'!$C$71,'Sheet1 (2)'!$D$71*('Sheet1 (2)'!$D$72-rave_index)/'Sheet1 (2)'!$D$72)))) -> 2.9166667 | AY15: =IF(IF(D15='Sheet1 (2)'!$C$69,'Sheet1 (2)'!$D$69*('Sheet1 (2)'!$D$72-rough_index)/'Sheet1 (2)'!$D$72,IF(shee2!D15='Sheet1 (2)'!$C$70,'Sheet1 (2)'!$D$70*('Sheet1 (2)'!$D$72-rough_index)/'Sheet1 (2)'!$D$72,IF(shee2!D15='Sheet1 (2)'!$C$71,'Sheet1 (2)'!$D$71*('Sheet1 (2)'!$D$72-rough_index)/'Sheet1 (2)'!$D$72)))<0,0,IF(D15='Sheet1 (2)'!$C$69,'Sheet1 (2)'!$D$69*('Sheet1 (2)'!$D$72-rough_index)/'Sheet1 (2)'!$D$72,IF(shee2!D15='Sheet1 (2)'!$C$70,'Sheet1 (2)'!$D$70*('Sheet1 (2)'!$D$72-rough_index)/'Sheet1 (2)'!$D$72,IF(shee2!D15='Sheet1 (2)'!$C$71,'Sheet1 (2)'!$D$71*('Sheet1 (2)'!$D$72-rough_index)/'Sheet1 (2)'!$D$72)))) -> 0 | AZ15: =+(AU15*'Sheet1 (2)'!$C$77)+(AV15*'Sheet1 (2)'!$C$78)+(AW15*'Sheet1 (2)'!$C$79)+(AX15*'Sheet1 (2)'!$C$80)+(AY15*'Sheet1 (2)'!$C$81) -> 3.2583333 | BA15: =IF(AZ15="",$AH15,IF(AZ15>=4,"Good",IF(AZ15>=2.5,"Fair",IF(AZ15>=1,"Poor",IF(AZ15>=0,"Very Poor",""))))) -> Fair | BE15: =IF(D15='Sheet1 (2)'!$C$61,'Sheet1 (2)'!$D$61*(counts^2)+'Sheet1 (2)'!$G$61*counts+'Sheet1 (2)'!$J$61,IF(D15='Sheet1 (2)'!$C$62,'Sheet1 (2)'!$D$62*counts+'Sheet1 (2)'!$G$62,IF(D15='Sheet1 (2)'!$C$63,'Sheet1 (2)'!$D$63*counts+'Sheet1 (2)'!$G$63,IF(D15='Sheet1 (2)'!$C$64,'Sheet1 (2)'!$D$64*counts+'Sheet1 (2)'!$G$64)))) -> 2.0984129
A16: N-5 | B16: NB | C16: 156 | D16: A | E16: 8 | F16: 1 | G16: A | H16: 0.5 | I16: A | J16: x | K16: x | L16: =VLOOKUP(CONCATENATE(J16,K16),'Sheet1 (2)'!$J$6:$K$26,2,FALSE) -> 0 | M16: x | N16: x | O16: =VLOOKUP(CONCATENATE(M16,N16),'Sheet1 (2)'!$L$6:$M$26,2,FALSE) -> 0 | P16: x | Q16: x | R16: =VLOOKUP(CONCATENATE(P16,Q16),'Sheet1 (2)'!$N$6:$O$26,2,FALSE) -> 0 | S16: x | T16: x | U16: =VLOOKUP(CONCATENATE(S16,T16),'Sheet1 (2)'!$P$6:$Q$26,2,FALSE) -> 0 | V16: x | W16: x | X16: =VLOOKUP(CONCATENATE(V16,W16),'Sheet1 (2)'!$R$6:$S$26,2,FALSE) -> 0 | Y16: x | Z16: x | AA16: =VLOOKUP(CONCATENATE(Y16,Z16),'Sheet1 (2)'!$T$6:$U$26,2,FALSE) -> 0 | AB16: x | AC16: x | AD16: =VLOOKUP(CONCATENATE(AB16,AC16),'Sheet1 (2)'!$X$6:$Y$26,2,FALSE) -> 0 | AE16: b | AF16: e | AG16: =VLOOKUP(CONCATENATE(AE16,AF16),'Sheet1 (2)'!$Z$6:$AA$26,2,FALSE) -> 66 | AK16: N-5 | AL16: NB | AM16: =C16 -> 156 | AQ16: 3.9475752 | AS16: =LOOKUP(rufmkm,'Sheet1 (2)'!$V$62:$V$71,'Sheet1 (2)'!$W$62:$W$71) -> 40 | AU16: =IF(IF(D16='Sheet1 (2)'!$C$69,'Sheet1 (2)'!$D$69*('Sheet1 (2)'!$D$72-rut_index)/'Sheet1 (2)'!$D$72,IF(shee2!D16='Sheet1 (2)'!$C$70,'Sheet1 (2)'!$D$70*('Sheet1 (2)'!$D$72-rut_index)/'Sheet1 (2)'!$D$72,IF(shee2!D16='Sheet1 (2)'!$C$71,'Sheet1 (2)'!$D$71*('Sheet1 (2)'!$D$72-rut_index)/'Sheet1 (2)'!$D$72)))<0,0,IF(D16='Sheet1 (2)'!$C$69,'Sheet1 (2)'!$D$69*('Sheet1 (2)'!$D$72-rut_index)/'Sheet1 (2)'!$D$72,IF(shee2!D16='Sheet1 (2)'!$C$70,'Sheet1 (2)'!$D$70*('Sheet1 (2)'!$D$72-rut_index)/'Sheet1 (2)'!$D$72,IF(shee2!D16='Sheet1 (2)'!$C$71,'Sheet1 (2)'!$D$71*('Sheet1 (2)'!$D$72-rut_index)/'Sheet1 (2)'!$D$72)))) -> 5 | AV16: =IF(IF(D16='Sheet1 (2)'!$C$69,'Sheet1 (2)'!$D$69*('Sheet1 (2)'!$D$72-crack_s_index)/'Sheet1 (2)'!$D$72,IF(shee2!D16='Sheet1 (2)'!$C$70,'Sheet1 (2)'!$D$70*('Sheet1 (2)'!$D$72-crack_s_index)/'Sheet1 (2)'!$D$72,IF(shee2!D16='Sheet1 (2)'!$C$71,'Sheet1 (2)'!$D$71*('Sheet1 (2)'!$D$72-crack_s_index)/'Sheet1 (2)'!$D$72)))<0,0,IF(D16='Sheet1 (2)'!$C$69,'Sheet1 (2)'!$D$69*('Sheet1 (2)'!$D$72-crack_s_index)/'Sheet1 (2)'!$D$72,IF(shee2!D16='Sheet1 (2)'!$C$70,'Sheet1 (2)'!$D$70*('Sheet1 (2)'!$D$72-crack_s_index)/'Sheet1 (2)'!$D$72,IF(shee2!D16='Sheet1 (2)'!$C$71,'Sheet1 (2)'!$D$71*('Sheet1 (2)'!$D$72-crack_s_index)/'Sheet1 (2)'!$D$72)))) -> 5 | AW16: =IF(IF(D16='Sheet1 (2)'!$C$69,'Sheet1 (2)'!$D$69*('Sheet1 (2)'!$D$72-crack_t_index)/'Sheet1 (2)'!$D$72,IF(shee2!D16='Sheet1 (2)'!$C$70,'Sheet1 (2)'!$D$70*('Sheet1 (2)'!$D$72-crack_t_index)/'Sheet1 (2)'!$D$72,IF(shee2!D16='Sheet1 (2)'!$C$71,'Sheet1 (2)'!$D$71*('Sheet1 (2)'!$D$72-crack_t_index)/'Sheet1 (2)'!$D$72)))<0,0,IF(D16='Sheet1 (2)'!$C$69,'Sheet1 (2)'!$D$69*('Sheet1 (2)'!$D$72-crack_t_index)/'Sheet1 (2)'!$D$72,IF(shee2!D16='Sheet1 (2)'!$C$70,'Sheet1 (2)'!$D$70*('Sheet1 (2)'!$D$72-crack_t_index)/'Sheet1 (2)'!$D$72,IF(shee2!D16='Sheet1 (2)'!$C$71,'Sheet1 (2)'!$D$71*('Sheet1 (2)'!$D$72-crack_t_index)/'Sheet1 (2)'!$D$72)))) -> 5 | AX16: =IF(IF(D16='Sheet1 (2)'!$C$69,'Sheet1 (2)'!$D$69*('Sheet1 (2)'!$D$72-rave_index)/'Sheet1 (2)'!$D$72,IF(shee2!D16='Sheet1 (2)'!$C$70,'Sheet1 (2)'!$D$70*('Sheet1 (2)'!$D$72-rave_index)/'Sheet1 (2)'!$D$72,IF(shee2!D16='Sheet1 (2)'!$C$71,'Sheet1 (2)'!$D$71*('Sheet1 (2)'!$D$72-rave_index)/'Sheet1 (2)'!$D$72)))<0,0,IF(D16='Sheet1 (2)'!$C$69,'Sheet1 (2)'!$D$69*('Sheet1 (2)'!$D$72-rave_index)/'Sheet1 (2)'!$D$72,IF(shee2!D16='Sheet1 (2)'!$C$70,'Sheet1 (2)'!$D$70*('Sheet1 (2)'!$D$72-rave_index)/'Sheet1 (2)'!$D$72,IF(shee2!D16='Sheet1 (2)'!$C$71,'Sheet1 (2)'!$D$71*('Sheet1 (2)'!$D$72-rave_index)/'Sheet1 (2)'!$D$72)))) -> 5 | AY16: =IF(IF(D16='Sheet1 (2)'!$C$69,'Sheet1 (2)'!$D$69*('Sheet1 (2)'!$D$72-rough_index)/'Sheet1 (2)'!$D$72,IF(shee2!D16='Sheet1 (2)'!$C$70,'Sheet1 (2)'!$D$70*('Sheet1 (2)'!$D$72-rough_index)/'Sheet1 (2)'!$D$72,IF(shee2!D16='Sheet1 (2)'!$C$71,'Sheet1 (2)'!$D$71*('Sheet1 (2)'!$D$72-rough_index)/'Sheet1 (2)'!$D$72)))<0,0,IF(D16='Sheet1 (2)'!$C$69,'Sheet1 (2)'!$D$69*('Sheet1 (2)'!$D$72-rough_index)/'Sheet1 (2)'!$D$72,IF(shee2!D16='Sheet1 (2)'!$C$70,'Sheet1 (2)'!$D$70*('Sheet1 (2)'!$D$72-rough_index)/'Sheet1 (2)'!$D$72,IF(shee2!D16='Sheet1 (2)'!$C$71,'Sheet1 (2)'!$D$71*('Sheet1 (2)'!$D$72-rough_index)/'Sheet1 (2)'!$D$72)))) -> 1.6666667 | AZ16: =+(AU16*'Sheet1 (2)'!$C$77)+(AV16*'Sheet1 (2)'!$C$78)+(AW16*'Sheet1 (2)'!$C$79)+(AX16*'Sheet1 (2)'!$C$80)+(AY16*'Sheet1 (2)'!$C$81) -> 4 | BA16: =IF(AZ16="",$AH16,IF(AZ16>=4,"Good",IF(AZ16>=2.5,"Fair",IF(AZ16>=1,"Poor",IF(AZ16>=0,"Very Poor",""))))) -> Good | BE16: =IF(D16='Sheet1 (2)'!$C$61,'Sheet1 (2)'!$D$61*(counts^2)+'Sheet1 (2)'!$G$61*counts+'Sheet1 (2)'!$J$61,IF(D16='Sheet1 (2)'!$C$62,'Sheet1 (2)'!$D$62*counts+'Sheet1 (2)'!$G$62,IF(D16='Sheet1 (2)'!$C$63,'Sheet1 (2)'!$D$63*counts+'Sheet1 (2)'!$G$63,IF(D16='Sheet1 (2)'!$C$64,'Sheet1 (2)'!$D$64*counts+'Sheet1 (2)'!$G$64)))) -> 2.0984129
A17: N-5 | B17: NB | C17: 157 | D17: A | E17: 8 | F17: 1 | G17: A | H17: 0.5 | I17: A | J17: x | K17: x | L17: =VLOOKUP(CONCATENATE(J17,K17),'Sheet1 (2)'!$J$6:$K$26,2,FALSE) -> 0 | M17: x | N17: x | O17: =VLOOKUP(CONCATENATE(M17,N17),'Sheet1 (2)'!$L$6:$M$26,2,FALSE) -> 0 | P17: x | Q17: x | R17: =VLOOKUP(CONCATENATE(P17,Q17),'Sheet1 (2)'!$N$6:$O$26,2,FALSE) -> 0 | S17: x | T17: x | U17: =VLOOKUP(CONCATENATE(S17,T17),'Sheet1 (2)'!$P$6:$Q$26,2,FALSE) -> 0 | V17: x | W17: x | X17: =VLOOKUP(CONCATENATE(V17,W17),'Sheet1 (2)'!$R$6:$S$26,2,FALSE) -> 0 | Y17: x | Z17: x | AA17: =VLOOKUP(CONCATENATE(Y17,Z17),'Sheet1 (2)'!$T$6:$U$26,2,FALSE) -> 0 | AB17: x | AC17: x | AD17: =VLOOKUP(CONCATENATE(AB17,AC17),'Sheet1 (2)'!$X$6:$Y$26,2,FALSE) -> 0 | AE17: b | AF17: e | AG17: =VLOOKUP(CONCATENATE(AE17,AF17),'Sheet1 (2)'!$Z$6:$AA$26,2,FALSE) -> 66 | AK17: N-5 | AL17: NB | AM17: =C17 -> 157 | AO17: Bridge | AQ17: 2.5876868 | AS17: =LOOKUP(rufmkm,'Sheet1 (2)'!$V$62:$V$71,'Sheet1 (2)'!$W$62:$W$71) -> 30 | AU17: =IF(IF(D17='Sheet1 (2)'!$C$69,'Sheet1 (2)'!$D$69*('Sheet1 (2)'!$D$72-rut_index)/'Sheet1 (2)'!$D$72,IF(shee2!D17='Sheet1 (2)'!$C$70,'Sheet1 (2)'!$D$70*('Sheet1 (2)'!$D$72-rut_index)/'Sheet1 (2)'!$D$72,IF(shee2!D17='Sheet1 (2)'!$C$71,'Sheet1 (2)'!$D$71*('Sheet1 (2)'!$D$72-rut_index)/'Sheet1 (2)'!$D$72)))<0,0,IF(D17='Sheet1 (2)'!$C$69,'Sheet1 (2)'!$D$69*('Sheet1 (2)'!$D$72-rut_index)/'Sheet1 (2)'!$D$72,IF(shee2!D17='Sheet1 (2)'!$C$70,'Sheet1 (2)'!$D$70*('Sheet1 (2)'!$D$72-rut_index)/'Sheet1 (2)'!$D$72,IF(shee2!D17='Sheet1 (2)'!$C$71,'Sheet1 (2)'!$D$71*('Sheet1 (2)'!$D$72-rut_index)/'Sheet1 (2)'!$D$72)))) -> 5 | AV17: =IF(IF(D17='Sheet1 (2)'!$C$69,'Sheet1 (2)'!$D$69*('Sheet1 (2)'!$D$72-crack_s_index)/'Sheet1 (2)'!$D$72,IF(shee2!D17='Sheet1 (2)'!$C$70,'Sheet1 (2)'!$D$70*('Sheet1 (2)'!$D$72-crack_s_index)/'Sheet1 (2)'!$D$72,IF(shee2!D17='Sheet1 (2)'!$C$71,'Sheet1 (2)'!$D$71*('Sheet1 (2)'!$D$72-crack_s_index)/'Sheet1 (2)'!$D$72)))<0,0,IF(D17='Sheet1 (2)'!$C$69,'Sheet1 (2)'!$D$69*('Sheet1 (2)'!$D$72-crack_s_index)/'Sheet1 (2)'!$D$72,IF(shee2!D17='Sheet1 (2)'!$C$70,'Sheet1 (2)'!$D$70*('Sheet1 (2)'!$D$72-crack_s_index)/'Sheet1 (2)'!$D$72,IF(shee2!D17='Sheet1 (2)'!$C$71,'Sheet1 (2)'!$D$71*('Sheet1 (2)'!$D$72-crack_s_index)/'Sheet1 (2)'!$D$72)))) -> 5 | AW17: =IF(IF(D17='Sheet1 (2)'!$C$69,'Sheet1 (2)'!$D$69*('Sheet1 (2)'!$D$72-crack_t_index)/'Sheet1 (2)'!$D$72,IF(shee2!D17='Sheet1 (2)'!$C$70,'Sheet1 (2)'!$D$70*('Sheet1 (2)'!$D$72-crack_t_index)/'Sheet1 (2)'!$D$72,IF(shee2!D17='Sheet1 (2)'!$C$71,'Sheet1 (2)'!$D$71*('Sheet1 (2)'!$D$72-crack_t_index)/'Sheet1 (2)'!$D$72)))<0,0,IF(D17='Sheet1 (2)'!$C$69,'Sheet1 (2)'!$D$69*('Sheet1 (2)'!$D$72-crack_t_index)/'Sheet1 (2)'!$D$72,IF(shee2!D17='Sheet1 (2)'!$C$70,'Sheet1 (2)'!$D$70*('Sheet1 (2)'!$D$72-crack_t_index)/'Sheet1 (2)'!$D$72,IF(shee2!D17='Sheet1 (2)'!$C$71,'Sheet1 (2)'!$D$71*('Sheet1 (2)'!$D$72-crack_t_index)/'Sheet1 (2)'!$D$72)))) -> 5 | AX17: =IF(IF(D17='Sheet1 (2)'!$C$69,'Sheet1 (2)'!$D$69*('Sheet1 (2)'!$D$72-rave_index)/'Sheet1 (2)'!$D$72,IF(shee2!D17='Sheet1 (2)'!$C$70,'Sheet1 (2)'!$D$70*('Sheet1 (2)'!$D$72-rave_index)/'Sheet1 (2)'!$D$72,IF(shee2!D17='Sheet1 (2)'!$C$71,'Sheet1 (2)'!$D$71*('Sheet1 (2)'!$D$72-rave_index)/'Sheet1 (2)'!$D$72)))<0,0,IF(D17='Sheet1 (2)'!$C$69,'Sheet1 (2)'!$D$69*('Sheet1 (2)'!$D$72-rave_index)/'Sheet1 (2)'!$D$72,IF(shee2!D17='Sheet1 (2)'!$C$70,'Sheet1 (2)'!$D$70*('Sheet1 (2)'!$D$72-rave_index)/'Sheet1 (2)'!$D$72,IF(shee2!D17='Sheet1 (2)'!$C$71,'Sheet1 (2)'!$D$71*('Sheet1 (2)'!$D$72-rave_index)/'Sheet1 (2)'!$D$72)))) -> 5 | AY17: =IF(IF(D17='Sheet1 (2)'!$C$69,'Sheet1 (2)'!$D$69*('Sheet1 (2)'!$D$72-rough_index)/'Sheet1 (2)'!$D$72,IF(shee2!D17='Sheet1 (2)'!$C$70,'Sheet1 (2)'!$D$70*('Sheet1 (2)'!$D$72-rough_index)/'Sheet1 (2)'!$D$72,IF(shee2!D17='Sheet1 (2)'!$C$71,'Sheet1 (2)'!$D$71*('Sheet1 (2)'!$D$72-rough_index)/'Sheet1 (2)'!$D$72)))<0,0,IF(D17='Sheet1 (2)'!$C$69,'Sheet1 (2)'!$D$69*('Sheet1 (2)'!$D$72-rough_index)/'Sheet1 (2)'!$D$72,IF(shee2!D17='Sheet1 (2)'!$C$70,'Sheet1 (2)'!$D$70*('Sheet1 (2)'!$D$72-rough_index)/'Sheet1 (2)'!$D$72,IF(shee2!D17='Sheet1 (2)'!$C$71,'Sheet1 (2)'!$D$71*('Sheet1 (2)'!$D$72-rough_index)/'Sheet1 (2)'!$D$72)))) -> 2.5 | AZ17: =+(AU17*'Sheet1 (2)'!$C$77)+(AV17*'Sheet1 (2)'!$C$78)+(AW17*'Sheet1 (2)'!$C$79)+(AX17*'Sheet1 (2)'!$C$80)+(AY17*'Sheet1 (2)'!$C$81) -> 4.25 | BA17: =IF(AZ17="",$AH17,IF(AZ17>=4,"Good",IF(AZ17>=2.5,"Fair",IF(AZ17>=1,"Poor",IF(AZ17>=0,"Very Poor",""))))) -> Good | BE17: =IF(D17='Sheet1 (2)'!$C$61,'Sheet1 (2)'!$D$61*(counts^2)+'Sheet1 (2)'!$G$61*counts+'Sheet1 (2)'!$J$61,IF(D17='Sheet1 (2)'!$C$62,'Sheet1 (2)'!$D$62*counts+'Sheet1 (2)'!$G$62,IF(D17='Sheet1 (2)'!$C$63,'Sheet1 (2)'!$D$63*counts+'Sheet1 (2)'!$G$63,IF(D17='Sheet1 (2)'!$C$64,'Sheet1 (2)'!$D$64*counts+'Sheet1 (2)'!$G$64)))) -> 2.0984129
A18: N-5 | B18: NB | C18: 158 | D18: A | E18: 8 | F18: 1 | G18: A | H18: 0.5 | I18: A | J18: x | K18: x | L18: =VLOOKUP(CONCATENATE(J18,K18),'Sheet1 (2)'!$J$6:$K$26,2,FALSE) -> 0 | M18: x | N18: x | O18: =VLOOKUP(CONCATENATE(M18,N18),'Sheet1 (2)'!$L$6:$M$26,2,FALSE) -> 0 | P18: x | Q18: x | R18: =VLOOKUP(CONCATENATE(P18,Q18),'Sheet1 (2)'!$N$6:$O$26,2,FALSE) -> 0 | S18: x | T18: x | U18: =VLOOKUP(CONCATENATE(S18,T18),'Sheet1 (2)'!$P$6:$Q$26,2,FALSE) -> 0 | V18: x | W18: x | X18: =VLOOKUP(CONCATENATE(V18,W18),'Sheet1 (2)'!$R$6:$S$26,2,FALSE) -> 0 | Y18: d | Z18: c | AA18: =VLOOKUP(CONCATENATE(Y18,Z18),'Sheet1 (2)'!$T$6:$U$26,2,FALSE) -> 50 | AB18: x | AC18: x | AD18: =VLOOKUP(CONCATENATE(AB18,AC18),'Sheet1 (2)'!$X$6:$Y$26,2,FALSE) -> 0 | AE18: b | AF18: e | AG18: =VLOOKUP(CONCATENATE(AE18,AF18),'Sheet1 (2)'!$Z$6:$AA$26,2,FALSE) -> 66 | AK18: N-5 | AL18: NB | AM18: =C18 -> 158 | AQ18: 2.5068235 | AS18: =LOOKUP(rufmkm,'Sheet1 (2)'!$V$62:$V$71,'Sheet1 (2)'!$W$62:$W$71) -> 30 | AU18: =IF(IF(D18='Sheet1 (2)'!$C$69,'Sheet1 (2)'!$D$69*('Sheet1 (2)'!$D$72-rut_index)/'Sheet1 (2)'!$D$72,IF(shee2!D18='Sheet1 (2)'!$C$70,'Sheet1 (2)'!$D$70*('Sheet1 (2)'!$D$72-rut_index)/'Sheet1 (2)'!$D$72,IF(shee2!D18='Sheet1 (2)'!$C$71,'Sheet1 (2)'!$D$71*('Sheet1 (2)'!$D$72-rut_index)/'Sheet1 (2)'!$D$72)))<0,0,IF(D18='Sheet1 (2)'!$C$69,'Sheet1 (2)'!$D$69*('Sheet1 (2)'!$D$72-rut_index)/'Sheet1 (2)'!$D$72,IF(shee2!D18='Sheet1 (2)'!$C$70,'Sheet1 (2)'!$D$70*('Sheet1 (2)'!$D$72-rut_index)/'Sheet1 (2)'!$D$72,IF(shee2!D18='Sheet1 (2)'!$C$71,'Sheet1 (2)'!$D$71*('Sheet1 (2)'!$D$72-rut_index)/'Sheet1 (2)'!$D$72)))) -> 5 | AV18: =IF(IF(D18='Sheet1 (2)'!$C$69,'Sheet1 (2)'!$D$69*('Sheet1 (2)'!$D$72-crack_s_index)/'Sheet1 (2)'!$D$72,IF(shee2!D18='Sheet1 (2)'!$C$70,'Sheet1 (2)'!$D$70*('Sheet1 (2)'!$D$72-crack_s_index)/'Sheet1 (2)'!$D$72,IF(shee2!D18='Sheet1 (2)'!$C$71,'Sheet1 (2)'!$D$71*('Sheet1 (2)'!$D$72-crack_s_index)/'Sheet1 (2)'!$D$72)))<0,0,IF(D18='Sheet1 (2)'!$C$69,'Sheet1 (2)'!$D$69*('Sheet1 (2)'!$D$72-crack_s_index)/'Sheet1 (2)'!$D$72,IF(shee2!D18='Sheet1 (2)'!$C$70,'Sheet1 (2)'!$D$70*('Sheet1 (2)'!$D$72-crack_s_index)/'Sheet1 (2)'!$D$72,IF(shee2!D18='Sheet1 (2)'!$C$71,'Sheet1 (2)'!$D$71*('Sheet1 (2)'!$D$72-crack_s_index)/'Sheet1 (2)'!$D$72)))) -> 5 | AW18: =IF(IF(D18='Sheet1 (2)'!$C$69,'Sheet1 (2)'!$D$69*('Sheet1 (2)'!$D$72-crack_t_index)/'Sheet1 (2)'!$D$72,IF(shee2!D18='Sheet1 (2)'!$C$70,'Sheet1 (2)'!$D$70*('Sheet1 (2)'!$D$72-crack_t_index)/'Sheet1 (2)'!$D$72,IF(shee2!D18='Sheet1 (2)'!$C$71,'Sheet1 (2)'!$D$71*('Sheet1 (2)'!$D$72-crack_t_index)/'Sheet1 (2)'!$D$72)))<0,0,IF(D18='Sheet1 (2)'!$C$69,'Sheet1 (2)'!$D$69*('Sheet1 (2)'!$D$72-crack_t_index)/'Sheet1 (2)'!$D$72,IF(shee2!D18='Sheet1 (2)'!$C$70,'Sheet1 (2)'!$D$70*('Sheet1 (2)'!$D$72-crack_t_index)/'Sheet1 (2)'!$D$72,IF(shee2!D18='Sheet1 (2)'!$C$71,'Sheet1 (2)'!$D$71*('Sheet1 (2)'!$D$72-crack_t_index)/'Sheet1 (2)'!$D$72)))) -> 5 | AX18: =IF(IF(D18='Sheet1 (2)'!$C$69,'Sheet1 (2)'!$D$69*('Sheet1 (2)'!$D$72-rave_index)/'Sheet1 (2)'!$D$72,IF(shee2!D18='Sheet1 (2)'!$C$70,'Sheet1 (2)'!$D$70*('Sheet1 (2)'!$D$72-rave_index)/'Sheet1 (2)'!$D$72,IF(shee2!D18='Sheet1 (2)'!$C$71,'Sheet1 (2)'!$D$71*('Sheet1 (2)'!$D$72-rave_index)/'Sheet1 (2)'!$D$72)))<0,0,IF(D18='Sheet1 (2)'!$C$69,'Sheet1 (2)'!$D$69*('Sheet1 (2)'!$D$72-rave_index)/'Sheet1 (2)'!$D$72,IF(shee2!D18='Sheet1 (2)'!$C$70,'Sheet1 (2)'!$D$70*('Sheet1 (2)'!$D$72-rave_index)/'Sheet1 (2)'!$D$72,IF(shee2!D18='Sheet1 (2)'!$C$71,'Sheet1 (2)'!$D$71*('Sheet1 (2)'!$D$72-rave_index)/'Sheet1 (2)'!$D$72)))) -> 0.83333333 | AY18: =IF(IF(D18='Sheet1 (2)'!$C$69,'Sheet1 (2)'!$D$69*('Sheet1 (2)'!$D$72-rough_index)/'Sheet1 (2)'!$D$72,IF(shee2!D18='Sheet1 (2)'!$C$70,'Sheet1 (2)'!$D$70*('Sheet1 (2)'!$D$72-rough_index)/'Sheet1 (2)'!$D$72,IF(shee2!D18='Sheet1 (2)'!$C$71,'Sheet1 (2)'!$D$71*('Sheet1 (2)'!$D$72-rough_index)/'Sheet1 (2)'!$D$72)))<0,0,IF(D18='Sheet1 (2)'!$C$69,'Sheet1 (2)'!$D$69*('Sheet1 (2)'!$D$72-rough_index)/'Sheet1 (2)'!$D$72,IF(shee2!D18='Sheet1 (2)'!$C$70,'Sheet1 (2)'!$D$70*('Sheet1 (2)'!$D$72-rough_index)/'Sheet1 (2)'!$D$72,IF(shee2!D18='Sheet1 (2)'!$C$71,'Sheet1 (2)'!$D$71*('Sheet1 (2)'!$D$72-rough_index)/'Sheet1 (2)'!$D$72)))) -> 2.5 | AZ18: =+(AU18*'Sheet1 (2)'!$C$77)+(AV18*'Sheet1 (2)'!$C$78)+(AW18*'Sheet1 (2)'!$C$79)+(AX18*'Sheet1 (2)'!$C$80)+(AY18*'Sheet1 (2)'!$C$81) -> 3.8333333 | BA18: =IF(AZ18="",$AH18,IF(AZ18>=4,"Good",IF(AZ18>=2.5,"Fair",IF(AZ18>=1,"Poor",IF(AZ18>=0,"Very Poor",""))))) -> Fair | BE18: =IF(D18='Sheet1 (2)'!$C$61,'Sheet1 (2)'!$D$61*(counts^2)+'Sheet1 (2)'!$G$61*counts+'Sheet1 (2)'!$J$61,IF(D18='Sheet1 (2)'!$C$62,'Sheet1 (2)'!$D$62*counts+'Sheet1 (2)'!$G$62,IF(D18='Sheet1 (2)'!$C$63,'Sheet1 (2)'!$D$63*counts+'Sheet1 (2)'!$G$63,IF(D18='Sheet1 (2)'!$C$64,'Sheet1 (2)'!$D$64*counts+'Sheet1 (2)'!$G$64)))) -> 2.0984129
A19: N-5 | B19: NB | C19: 159 | D19: A | E19: 8 | F19: 1 | G19: A | H19: 0.5 | I19: A | J19: x | K19: x | L19: =VLOOKUP(CONCATENATE(J19,K19),'Sheet1 (2)'!$J$6:$K$26,2,FALSE) -> 0 | M19: d | N19: b | O19: =VLOOKUP(CONCATENATE(M19,N19),'Sheet1 (2)'!$L$6:$M$26,2,FALSE) -> 25 | P19: d | Q19: b | R19: =VLOOKUP(CONCATENATE(P19,Q19),'Sheet1 (2)'!$N$6:$O$26,2,FALSE) -> 25 | S19: b | T19: d | U19: =VLOOKUP(CONCATENATE(S19,T19),'Sheet1 (2)'!$P$6:$Q$26,2,FALSE) -> 37.5 | V19: x | W19: x | X19: =VLOOKUP(CONCATENATE(V19,W19),'Sheet1 (2)'!$R$6:$S$26,2,FALSE) -> 0 | Y19: d | Z19: c | AA19: =VLOOKUP(CONCATENATE(Y19,Z19),'Sheet1 (2)'!$T$6:$U$26,2,FALSE) -> 50 | AB19: x | AC19: x | AD19: =VLOOKUP(CONCATENATE(AB19,AC19),'Sheet1 (2)'!$X$6:$Y$26,2,FALSE) -> 0 | AE19: b | AF19: e | AG19: =VLOOKUP(CONCATENATE(AE19,AF19),'Sheet1 (2)'!$Z$6:$AA$26,2,FALSE) -> 66 | AK19: N-5 | AL19: NB | AM19: =C19 -> 159 | AQ19: 3.4456689 | AS19: =LOOKUP(rufmkm,'Sheet1 (2)'!$V$62:$V$71,'Sheet1 (2)'!$W$62:$W$71) -> 40 | AU19: =IF(IF(D19='Sheet1 (2)'!$C$69,'Sheet1 (2)'!$D$69*('Sheet1 (2)'!$D$72-rut_index)/'Sheet1 (2)'!$D$72,IF(shee2!D19='Sheet1 (2)'!$C$70,'Sheet1 (2)'!$D$70*('Sheet1 (2)'!$D$72-rut_index)/'Sheet1 (2)'!$D$72,IF(shee2!D19='Sheet1 (2)'!$C$71,'Sheet1 (2)'!$D$71*('Sheet1 (2)'!$D$72-rut_index)/'Sheet1 (2)'!$D$72)))<0,0,IF(D19='Sheet1 (2)'!$C$69,'Sheet1 (2)'!$D$69*('Sheet1 (2)'!$D$72-rut_index)/'Sheet1 (2)'!$D$72,IF(shee2!D19='Sheet1 (2)'!$C$70,'Sheet1 (2)'!$D$70*('Sheet1 (2)'!$D$72-rut_index)/'Sheet1 (2)'!$D$72,IF(shee2!D19='Sheet1 (2)'!$C$71,'Sheet1 (2)'!$D$71*('Sheet1 (2)'!$D$72-rut_index)/'Sheet1 (2)'!$D$72)))) -> 5 | AV19: =IF(IF(D19='Sheet1 (2)'!$C$69,'Sheet1 (2)'!$D$69*('Sheet1 (2)'!$D$72-crack_s_index)/'Sheet1 (2)'!$D$72,IF(shee2!D19='Sheet1 (2)'!$C$70,'Sheet1 (2)'!$D$70*('Sheet1 (2)'!$D$72-crack_s_index)/'Sheet1 (2)'!$D$72,IF(shee2!D19='Sheet1 (2)'!$C$71,'Sheet1 (2)'!$D$71*('Sheet1 (2)'!$D$72-crack_s_index)/'Sheet1 (2)'!$D$72)))<0,0,IF(D19='Sheet1 (2)'!$C$69,'Sheet1 (2)'!$D$69*('Sheet1 (2)'!$D$72-crack_s_index)/'Sheet1 (2)'!$D$72,IF(shee2!D19='Sheet1 (2)'!$C$70,'Sheet1 (2)'!$D$70*('Sheet1 (2)'!$D$72-crack_s_index)/'Sheet1 (2)'!$D$72,IF(shee2!D19='Sheet1 (2)'!$C$71,'Sheet1 (2)'!$D$71*('Sheet1 (2)'!$D$72-crack_s_index)/'Sheet1 (2)'!$D$72)))) -> 2.9166667 | AW19: =IF(IF(D19='Sheet1 (2)'!$C$69,'Sheet1 (2)'!$D$69*('Sheet1 (2)'!$D$72-crack_t_index)/'Sheet1 (2)'!$D$72,IF(shee2!D19='Sheet1 (2)'!$C$70,'Sheet1 (2)'!$D$70*('Sheet1 (2)'!$D$72-crack_t_index)/'Sheet1 (2)'!$D$72,IF(shee2!D19='Sheet1 (2)'!$C$71,'Sheet1 (2)'!$D$71*('Sheet1 (2)'!$D$72-crack_t_index)/'Sheet1 (2)'!$D$72)))<0,0,IF(D19='Sheet1 (2)'!$C$69,'Sheet1 (2)'!$D$69*('Sheet1 (2)'!$D$72-crack_t_index)/'Sheet1 (2)'!$D$72,IF(shee2!D19='Sheet1 (2)'!$C$70,'Sheet1 (2)'!$D$70*('Sheet1 (2)'!$D$72-crack_t_index)/'Sheet1 (2)'!$D$72,IF(shee2!D19='Sheet1 (2)'!$C$71,'Sheet1 (2)'!$D$71*('Sheet1 (2)'!$D$72-crack_t_index)/'Sheet1 (2)'!$D$72)))) -> 2.9166667 | AX19: =IF(IF(D19='Sheet1 (2)'!$C$69,'Sheet1 (2)'!$D$69*('Sheet1 (2)'!$D$72-rave_index)/'Sheet1 (2)'!$D$72,IF(shee2!D19='Sheet1 (2)'!$C$70,'Sheet1 (2)'!$D$70*('Sheet1 (2)'!$D$72-rave_index)/'Sheet1 (2)'!$D$72,IF(shee2!D19='Sheet1 (2)'!$C$71,'Sheet1 (2)'!$D$71*('Sheet1 (2)'!$D$72-rave_index)/'Sheet1 (2)'!$D$72)))<0,0,IF(D19='Sheet1 (2)'!$C$69,'Sheet1 (2)'!$D$69*('Sheet1 (2)'!$D$72-rave_index)/'Sheet1 (2)'!$D$72,IF(shee2!D19='Sheet1 (2)'!$C$70,'Sheet1 (2)'!$D$70*('Sheet1 (2)'!$D$72-rave_index)/'Sheet1 (2)'!$D$72,IF(shee2!D19='Sheet1 (2)'!$C$71,'Sheet1 (2)'!$D$71*('Sheet1 (2)'!$D$72-rave_index)/'Sheet1 (2)'!$D$72)))) -> 0.83333333 | AY19: =IF(IF(D19='Sheet1 (2)'!$C$69,'Sheet1 (2)'!$D$69*('Sheet1 (2)'!$D$72-rough_index)/'Sheet1 (2)'!$D$72,IF(shee2!D19='Sheet1 (2)'!$C$70,'Sheet1 (2)'!$D$70*('Sheet1 (2)'!$D$72-rough_index)/'Sheet1 (2)'!$D$72,IF(shee2!D19='Sheet1 (2)'!$C$71,'Sheet1 (2)'!$D$71*('Sheet1 (2)'!$D$72-rough_index)/'Sheet1 (2)'!$D$72)))<0,0,IF(D19='Sheet1 (2)'!$C$69,'Sheet1 (2)'!$D$69*('Sheet1 (2)'!$D$72-rough_index)/'Sheet1 (2)'!$D$72,IF(shee2!D19='Sheet1 (2)'!$C$70,'Sheet1 (2)'!$D$70*('Sheet1 (2)'!$D$72-rough_index)/'Sheet1 (2)'!$D$72,IF(shee2!D19='Sheet1 (2)'!$C$71,'Sheet1 (2)'!$D$71*('Sheet1 (2)'!$D$72-rough_index)/'Sheet1 (2)'!$D$72)))) -> 1.6666667 | AZ19: =+(AU19*'Sheet1 (2)'!$C$77)+(AV19*'Sheet1 (2)'!$C$78)+(AW19*'Sheet1 (2)'!$C$79)+(AX19*'Sheet1 (2)'!$C$80)+(AY19*'Sheet1 (2)'!$C$81) -> 2.75 | BA19: =IF(AZ19="",$AH19,IF(AZ19>=4,"Good",IF(AZ19>=2.5,"Fair",IF(AZ19>=1,"Poor",IF(AZ19>=0,"Very Poor",""))))) -> Fair | BE19: =IF(D19='Sheet1 (2)'!$C$61,'Sheet1 (2)'!$D$61*(counts^2)+'Sheet1 (2)'!$G$61*counts+'Sheet1 (2)'!$J$61,IF(D19='Sheet1 (2)'!$C$62,'Sheet1 (2)'!$D$62*counts+'Sheet1 (2)'!$G$62,IF(D19='Sheet1 (2)'!$C$63,'Sheet1 (2)'!$D$63*counts+'Sheet1 (2)'!$G$63,IF(D19='Sheet1 (2)'!$C$64,'Sheet1 (2)'!$D$64*counts+'Sheet1 (2)'!$G$64)))) -> 2.0984129
A20: N-5 | B20: NB | C20: 160 | D20: A | E20: 8 | F20: 1 | G20: A | H20: 0.5 | I20: A | J20: b | K20: c | L20: =VLOOKUP(CONCATENATE(J20,K20),'Sheet1 (2)'!$J$6:$K$26,2,FALSE) -> 25 | M20: x | N20: x | O20: =VLOOKUP(CONCATENATE(M20,N20),'Sheet1 (2)'!$L$6:$M$26,2,FALSE) -> 0 | P20: x | Q20: x | R20: =VLOOKUP(CONCATENATE(P20,Q20),'Sheet1 (2)'!$N$6:$O$26,2,FALSE) -> 0 | S20: x | T20: x | U20: =VLOOKUP(CONCATENATE(S20,T20),'Sheet1 (2)'!$P$6:$Q$26,2,FALSE) -> 0 | V20: x | W20: x | X20: =VLOOKUP(CONCATENATE(V20,W20),'Sheet1 (2)'!$R$6:$S$26,2,FALSE) -> 0 | Y20: c | Z20: b | AA20: =VLOOKUP(CONCATENATE(Y20,Z20),'Sheet1 (2)'!$T$6:$U$26,2,FALSE) -> 18.75 | AB20: x | AC20: x | AD20: =VLOOKUP(CONCATENATE(AB20,AC20),'Sheet1 (2)'!$X$6:$Y$26,2,FALSE) -> 0 | AE20: b | AF20: e | AG20: =VLOOKUP(CONCATENATE(AE20,AF20),'Sheet1 (2)'!$Z$6:$AA$26,2,FALSE) -> 66 | AK20: N-5 | AL20: NB | AM20: =C20 -> 160 | AQ20: 3.6856794 | AS20: =LOOKUP(rufmkm,'Sheet1 (2)'!$V$62:$V$71,'Sheet1 (2)'!$W$62:$W$71) -> 40 | AU20: =IF(IF(D20='Sheet1 (2)'!$C$69,'Sheet1 (2)'!$D$69*('Sheet1 (2)'!$D$72-rut_index)/'Sheet1 (2)'!$D$72,IF(shee2!D20='Sheet1 (2)'!$C$70,'Sheet1 (2)'!$D$70*('Sheet1 (2)'!$D$72-rut_index)/'Sheet1 (2)'!$D$72,IF(shee2!D20='Sheet1 (2)'!$C$71,'Sheet1 (2)'!$D$71*('Sheet1 (2)'!$D$72-rut_index)/'Sheet1 (2)'!$D$72)))<0,0,IF(D20='Sheet1 (2)'!$C$69,'Sheet1 (2)'!$D$69*('Sheet1 (2)'!$D$72-rut_index)/'Sheet1 (2)'!$D$72,IF(shee2!D20='Sheet1 (2)'!$C$70,'Sheet1 (2)'!$D$70*('Sheet1 (2)'!$D$72-rut_index)/'Sheet1 (2)'!$D$72,IF(shee2!D20='Sheet1 (2)'!$C$71,'Sheet1 (2)'!$D$71*('Sheet1 (2)'!$D$72-rut_index)/'Sheet1 (2)'!$D$72)))) -> 2.9166667 | AV20: =IF(IF(D20='Sheet1 (2)'!$C$69,'Sheet1 (2)'!$D$69*('Sheet1 (2)'!$D$72-crack_s_index)/'Sheet1 (2)'!$D$72,IF(shee2!D20='Sheet1 (2)'!$C$70,'Sheet1 (2)'!$D$70*('Sheet1 (2)'!$D$72-crack_s_index)/'Sheet1 (2)'!$D$72,IF(shee2!D20='Sheet1 (2)'!$C$71,'Sheet1 (2)'!$D$71*('Sheet1 (2)'!$D$72-crack_s_index)/'Sheet1 (2)'!$D$72)))<0,0,IF(D20='Sheet1 (2)'!$C$69,'Sheet1 (2)'!$D$69*('Sheet1 (2)'!$D$72-crack_s_index)/'Sheet1 (2)'!$D$72,IF(shee2!D20='Sheet1 (2)'!$C$70,'Sheet1 (2)'!$D$70*('Sheet1 (2)'!$D$72-crack_s_index)/'Sheet1 (2)'!$D$72,IF(shee2!D20='Sheet1 (2)'!$C$71,'Sheet1 (2)'!$D$71*('Sheet1 (2)'!$D$72-crack_s_index)/'Sheet1 (2)'!$D$72)))) -> 5 | AW20: =IF(IF(D20='Sheet1 (2)'!$C$69,'Sheet1 (2)'!$D$69*('Sheet1 (2)'!$D$72-crack_t_index)/'Sheet1 (2)'!$D$72,IF(shee2!D20='Sheet1 (2)'!$C$70,'Sheet1 (2)'!$D$70*('Sheet1 (2)'!$D$72-crack_t_index)/'Sheet1 (2)'!$D$72,IF(shee2!D20='Sheet1 (2)'!$C$71,'Sheet1 (2)'!$D$71*('Sheet1 (2)'!$D$72-crack_t_index)/'Sheet1 (2)'!$D$72)))<0,0,IF(D20='Sheet1 (2)'!$C$69,'Sheet1 (2)'!$D$69*('Sheet1 (2)'!$D$72-crack_t_index)/'Sheet1 (2)'!$D$72,IF(shee2!D20='Sheet1 (2)'!$C$70,'Sheet1 (2)'!$D$70*('Sheet1 (2)'!$D$72-crack_t_index)/'Sheet1 (2)'!$D$72,IF(shee2!D20='Sheet1 (2)'!$C$71,'Sheet1 (2)'!$D$71*('Sheet1 (2)'!$D$72-crack_t_index)/'Sheet1 (2)'!$D$72)))) -> 5 | AX20: =IF(IF(D20='Sheet1 (2)'!$C$69,'Sheet1 (2)'!$D$69*('Sheet1 (2)'!$D$72-rave_index)/'Sheet1 (2)'!$D$72,IF(shee2!D20='Sheet1 (2)'!$C$70,'Sheet1 (2)'!$D$70*('Sheet1 (2)'!$D$72-rave_index)/'Sheet1 (2)'!$D$72,IF(shee2!D20='Sheet1 (2)'!$C$71,'Sheet1 (2)'!$D$71*('Sheet1 (2)'!$D$72-rave_index)/'Sheet1 (2)'!$D$72)))<0,0,IF(D20='Sheet1 (2)'!$C$69,'Sheet1 (2)'!$D$69*('Sheet1 (2)'!$D$72-rave_index)/'Sheet1 (2)'!$D$72,IF(shee2!D20='Sheet1 (2)'!$C$70,'Sheet1 (2)'!$D$70*('Sheet1 (2)'!$D$72-rave_index)/'Sheet1 (2)'!$D$72,IF(shee2!D20='Sheet1 (2)'!$C$71,'Sheet1 (2)'!$D$71*('Sheet1 (2)'!$D$72-rave_index)/'Sheet1 (2)'!$D$72)))) -> 3.4375 | AY20: =IF(IF(D20='Sheet1 (2)'!$C$69,'Sheet1 (2)'!$D$69*('Sheet1 (2)'!$D$72-rough_index)/'Sheet1 (2)'!$D$72,IF(shee2!D20='Sheet1 (2)'!$C$70,'Sheet1 (2)'!$D$70*('Sheet1 (2)'!$D$72-rough_index)/'Sheet1 (2)'!$D$72,IF(shee2!D20='Sheet1 (2)'!$C$71,'Sheet1 (2)'!$D$71*('Sheet1 (2)'!$D$72-rough_index)/'Sheet1 (2)'!$D$72)))<0,0,IF(D20='Sheet1 (2)'!$C$69,'Sheet1 (2)'!$D$69*('Sheet1 (2)'!$D$72-rough_index)/'Sheet1 (2)'!$D$72,IF(shee2!D20='Sheet1 (2)'!$C$70,'Sheet1 (2)'!$D$70*('Sheet1 (2)'!$D$72-rough_index)/'Sheet1 (2)'!$D$72,IF(shee2!D20='Sheet1 (2)'!$C$71,'Sheet1 (2)'!$D$71*('Sheet1 (2)'!$D$72-rough_index)/'Sheet1 (2)'!$D$72)))) -> 1.6666667 | AZ20: =+(AU20*'Sheet1 (2)'!$C$77)+(AV20*'Sheet1 (2)'!$C$78)+(AW20*'Sheet1 (2)'!$C$79)+(AX20*'Sheet1 (2)'!$C$80)+(AY20*'Sheet1 (2)'!$C$81) -> 3.4270833 | BA20: =IF(AZ20="",$AH20,IF(AZ20>=4,"Good",IF(AZ20>=2.5,"Fair",IF(AZ20>=1,"Poor",IF(AZ20>=0,"Very Poor",""))))) -> Fair | BE20: =IF(D20='Sheet1 (2)'!$C$61,'Sheet1 (2)'!$D$61*(counts^2)+'Sheet1 (2)'!$G$61*counts+'Sheet1 (2)'!$J$61,IF(D20='Sheet1 (2)'!$C$62,'Sheet1 (2)'!$D$62*counts+'Sheet1 (2)'!$G$62,IF(D20='Sheet1 (2)'!$C$63,'Sheet1 (2)'!$D$63*counts+'Sheet1 (2)'!$G$63,IF(D20='Sheet1 (2)'!$C$64,'Sheet1 (2)'!$D$64*counts+'Sheet1 (2)'!$G$64)))) -> 2.0984129
